Workbook
Name Client: FILEPATH!$B$30
Name Date: FILEPATH!$B$33
Name Directory: #REF!
Name Directory: #REF!
Name FTE: FILEPATH!$K$3
Name HRS: FILEPATH!$K$2
Name Location: FILEPATH!#REF!
Name MAIT_date_adjusted_for_example: FILEPATH!$C$1
Name Max_HRS: Carer!$P$2
Name Max_HRS: RN!$P$2
Name Type: FILEPATH!$B$31
Name UNIT: Carer!$M$2
Name UNIT: 'CARER (2)'!$F$1
Name UNIT: RN!$M$2

Sheet CARER (2)
C1: CHOOSE UNITS: | E1: HRS | F1: =_xlfn.XLOOKUP('CARER (2)'!E1,Table5[UNITS],Table5[HRS/FTE]) -> 1
A3: =Header!B10 -> Facility | B3: =Header!C10 -> EffortType | C3: =Header!D10 -> Role | D3: =Header!E10 -> 19/06 AM | E3: =Header!F10 -> 19/06 PM | F3: =Header!G10 -> 19/06 NIGHT | G3: =Header!H10 -> 20/06 AM | H3: =Header!I10 -> 20/06 PM | ... AS3: =Header!AT10 -> 2/07 NIGHT
A4: =Header!B11 -> MAIT | B4: =Header!C11 -> Demand | C4: =Header!D11 -> Carer | D4: =Header!E11/UNIT -> 84.8 | E4: =Header!F11/UNIT -> 68.3 | F4: =Header!G11/UNIT -> 37 | G4: =Header!H11/UNIT -> 87.5 | H4: =Header!I11/UNIT -> 68.3 | I4: =Header!J11/UNIT -> 37 | J4: =Header!K11/UNIT -> 87.5 | K4: =Header!L11/UNIT -> 68.3 | ... AS4: =Header!AT11/UNIT -> 37
A5: =Header!B12 -> MAIT | B5: =Header!C12 -> Allocation | C5: =Header!D12 -> Carer | D5: =Header!E12/UNIT -> 84.2 | E5: =Header!F12/UNIT -> 65.5 | F5: =Header!G12/UNIT -> 35.9 | G5: =Header!H12/UNIT -> 87.5 | H5: =Header!I12/UNIT -> 72.3 | I5: =Header!J12/UNIT -> 35.9 | J5: =Header!K12/UNIT -> 80.4 | K5: =Header!L12/UNIT -> 72.3 | ... AS5: =Header!AT12/UNIT -> 16
A6: =Header!#REF! -> #REF! | B6: =Header!#REF! -> #REF! | C6: =Header!#REF! -> #REF! | D6: =Header!#REF!/UNIT -> #REF! | E6: =Header!#REF!/UNIT -> #REF! | F6: =Header!#REF!/UNIT -> #REF! | G6: =Header!#REF!/UNIT -> #REF! | H6: =Header!#REF!/UNIT -> #REF! | I6: =Header!#REF!/UNIT -> #REF! | J6: =Header!#REF!/UNIT -> #REF! | K6: =Header!#REF!/UNIT -> #REF! | ... AS6: =Header!#REF!/UNIT -> #REF!
B7: HeadCount | D7: =Header!#REF!/UNIT -> #REF! | E7: =Header!#REF!/UNIT -> #REF! | F7: =Header!#REF!/UNIT -> #REF! | G7: =Header!#REF!/UNIT -> #REF! | H7: =Header!#REF!/UNIT -> #REF! | I7: =Header!#REF!/UNIT -> #REF! | J7: =Header!#REF!/UNIT -> #REF! | K7: =Header!#REF!/UNIT -> #REF! | ... AS7: =Header!#REF!/UNIT -> #REF!
B8: Change | D8: =Header!#REF!/UNIT -> #REF! | E8: =Header!#REF!/UNIT -> #REF! | F8: =Header!#REF!/UNIT -> #REF! | G8: =Header!#REF!/UNIT -> #REF! | H8: =Header!#REF!/UNIT -> #REF! | I8: =Header!#REF!/UNIT -> #REF! | J8: =Header!#REF!/UNIT -> #REF! | K8: =Header!#REF!/UNIT -> #REF! | ... AS8: =Header!#REF!/UNIT -> #REF!
B9: Remaining GAP | D9: =Header!#REF!/UNIT -> #REF! | E9: =Header!#REF!/UNIT -> #REF! | F9: =Header!#REF!/UNIT -> #REF! | G9: =Header!#REF!/UNIT -> #REF! | H9: =Header!#REF!/UNIT -> #REF! | I9: =Header!#REF!/UNIT -> #REF! | J9: =Header!#REF!/UNIT -> #REF! | K9: =Header!#REF!/UNIT -> #REF! | ... AS9: =Header!#REF!/UNIT -> #REF!
B12: NAME | C12: Column1 | D12: 1 | E12: 2 | F12: 3 | G12: 4 | H12: 5 | I12: 6 | J12: 7 | K12: 8 | L12: 9 | M12: 10 | N12: 11 | O12: 12 | P12: 13 | Q12: 14 | R12: 15 | S12: 16 | T12: 17 | U12: 18 | V12: 19 | W12: 20 | X12: 21 | Y12: 22 | Z12: 23 | AA12: 24 | AB12: 25 | AC12: 26 | AD12: 27 | AE12: 28 | AF12: 29 | AG12: 30 | AH12: 31 | AI12: 32 | AJ12: 33 | AK12: 34 | AL12: 35 | AM12: 36 | AN12: 37 | AO12: 38 | AP12: 39 | AQ12: 40 | AR12: 41 | AS12: 42
A13: ='Residual-Rostered'!#REF! -> #REF! | B13: ='Residual-Rostered'!#REF! -> #REF! | C13: ='Residual-Rostered'!#REF! -> #REF! | D13: =IF('Residual-Rostered'!#REF!=0,"-",'Residual-Rostered'!#REF!) -> #REF! | E13: =IF('Residual-Rostered'!#REF!=0,"-",'Residual-Rostered'!#REF!) -> #REF! | F13: =IF('Residual-Rostered'!#REF!=0,"-",'Residual-Rostered'!#REF!) -> #REF! | G13: =IF('Residual-Rostered'!#REF!=0,"-",'Residual-Rostered'!#REF!) -> #REF! | H13: =IF('Residual-Rostered'!#REF!=0,"-",'Residual-Rostered'!#REF!) -> #REF! | I13: =IF('Residual-Rostered'!#REF!=0,"-",'Residual-Rostered'!#REF!) -> #REF! | J13: =IF('Residual-Rostered'!#REF!=0,"-",'Residual-Rostered'!#REF!) -> #REF! | K13: =IF('Residual-Rostered'!#REF!=0,"-",'Residual-Rostered'!#REF!) -> #REF! | ... AS13: =IF('Residual-Rostered'!#REF!=0,"-",'Residual-Rostered'!#REF!) -> #REF!
A14: ='Residual-Rostered'!#REF! -> #REF! | B14: ='Residual-Rostered'!#REF! -> #REF! | C14: ='Residual-Rostered'!#REF! -> #REF! | D14: =IF('Residual-Rostered'!#REF!=0,"-",'Residual-Rostered'!#REF!) -> #REF! | E14: =IF('Residual-Rostered'!#REF!=0,"-",'Residual-Rostered'!#REF!) -> #REF! | F14: =IF('Residual-Rostered'!#REF!=0,"-",'Residual-Rostered'!#REF!) -> #REF! | G14: =IF('Residual-Rostered'!#REF!=0,"-",'Residual-Rostered'!#REF!) -> #REF! | H14: =IF('Residual-Rostered'!#REF!=0,"-",'Residual-Rostered'!#REF!) -> #REF! | I14: =IF('Residual-Rostered'!#REF!=0,"-",'Residual-Rostered'!#REF!) -> #REF! | J14: =IF('Residual-Rostered'!#REF!=0,"-",'Residual-Rostered'!#REF!) -> #REF! | K14: =IF('Residual-Rostered'!#REF!=0,"-",'Residual-Rostered'!#REF!) -> #REF! | ... AS14: =IF('Residual-Rostered'!#REF!=0,"-",'Residual-Rostered'!#REF!) -> #REF!
A15: ='Residual-Rostered'!#REF! -> #REF! | B15: ='Residual-Rostered'!#REF! -> #REF! | C15: ='Residual-Rostered'!#REF! -> #REF! | D15: =IF('Residual-Rostered'!#REF!=0,"-",'Residual-Rostered'!#REF!) -> #REF! | E15: =IF('Residual-Rostered'!#REF!=0,"-",'Residual-Rostered'!#REF!) -> #REF! | F15: =IF('Residual-Rostered'!#REF!=0,"-",'Residual-Rostered'!#REF!) -> #REF! | G15: =IF('Residual-Rostered'!#REF!=0,"-",'Residual-Rostered'!#REF!) -> #REF! | H15: =IF('Residual-Rostered'!#REF!=0,"-",'Residual-Rostered'!#REF!) -> #REF! | I15: =IF('Residual-Rostered'!#REF!=0,"-",'Residual-Rostered'!#REF!) -> #REF! | J15: =IF('Residual-Rostered'!#REF!=0,"-",'Residual-Rostered'!#REF!) -> #REF! | K15: =IF('Residual-Rostered'!#REF!=0,"-",'Residual-Rostered'!#REF!) -> #REF! | ... AS15: =IF('Residual-Rostered'!#REF!=0,"-",'Residual-Rostered'!#REF!) -> #REF!
A16: ='Residual-Rostered'!#REF! -> #REF! | B16: ='Residual-Rostered'!#REF! -> #REF! | C16: ='Residual-Rostered'!#REF! -> #REF! | D16: =IF('Residual-Rostered'!#REF!=0,"-",'Residual-Rostered'!#REF!) -> #REF! | E16: =IF('Residual-Rostered'!#REF!=0,"-",'Residual-Rostered'!#REF!) -> #REF! | F16: =IF('Residual-Rostered'!#REF!=0,"-",'Residual-Rostered'!#REF!) -> #REF! | G16: =IF('Residual-Rostered'!#REF!=0,"-",'Residual-Rostered'!#REF!) -> #REF! | H16: =IF('Residual-Rostered'!#REF!=0,"-",'Residual-Rostered'!#REF!) -> #REF! | I16: =IF('Residual-Rostered'!#REF!=0,"-",'Residual-Rostered'!#REF!) -> #REF! | J16: =IF('Residual-Rostered'!#REF!=0,"-",'Residual-Rostered'!#REF!) -> #REF! | K16: =IF('Residual-Rostered'!#REF!=0,"-",'Residual-Rostered'!#REF!) -> #REF! | ... AS16: =IF('Residual-Rostered'!#REF!=0,"-",'Residual-Rostered'!#REF!) -> #REF!
A17: ='Residual-Rostered'!#REF! -> #REF! | B17: ='Residual-Rostered'!#REF! -> #REF! | C17: ='Residual-Rostered'!#REF! -> #REF! | D17: =IF('Residual-Rostered'!#REF!=0,"-",'Residual-Rostered'!#REF!) -> #REF! | E17: =IF('Residual-Rostered'!#REF!=0,"-",'Residual-Rostered'!#REF!) -> #REF! | F17: =IF('Residual-Rostered'!#REF!=0,"-",'Residual-Rostered'!#REF!) -> #REF! | G17: =IF('Residual-Rostered'!#REF!=0,"-",'Residual-Rostered'!#REF!) -> #REF! | H17: =IF('Residual-Rostered'!#REF!=0,"-",'Residual-Rostered'!#REF!) -> #REF! | I17: =IF('Residual-Rostered'!#REF!=0,"-",'Residual-Rostered'!#REF!) -> #REF! | J17: =IF('Residual-Rostered'!#REF!=0,"-",'Residual-Rostered'!#REF!) -> #REF! | K17: =IF('Residual-Rostered'!#REF!=0,"-",'Residual-Rostered'!#REF!) -> #REF! | ... AS17: =IF('Residual-Rostered'!#REF!=0,"-",'Residual-Rostered'!#REF!) -> #REF!
A18: ='Residual-Rostered'!#REF! -> #REF! | B18: ='Residual-Rostered'!#REF! -> #REF! | C18: ='Residual-Rostered'!#REF! -> #REF! | D18: =IF('Residual-Rostered'!#REF!=0,"-",'Residual-Rostered'!#REF!) -> #REF! | E18: =IF('Residual-Rostered'!#REF!=0,"-",'Residual-Rostered'!#REF!) -> #REF! | F18: =IF('Residual-Rostered'!#REF!=0,"-",'Residual-Rostered'!#REF!) -> #REF! | G18: =IF('Residual-Rostered'!#REF!=0,"-",'Residual-Rostered'!#REF!) -> #REF! | H18: =IF('Residual-Rostered'!#REF!=0,"-",'Residual-Rostered'!#REF!) -> #REF! | I18: =IF('Residual-Rostered'!#REF!=0,"-",'Residual-Rostered'!#REF!) -> #REF! | J18: =IF('Residual-Rostered'!#REF!=0,"-",'Residual-Rostered'!#REF!) -> #REF! | K18: =IF('Residual-Rostered'!#REF!=0,"-",'Residual-Rostered'!#REF!) -> #REF! | ... AS18: =IF('Residual-Rostered'!#REF!=0,"-",'Residual-Rostered'!#REF!) -> #REF!
A19: ='Residual-Rostered'!#REF! -> #REF! | B19: ='Residual-Rostered'!#REF! -> #REF! | C19: ='Residual-Rostered'!#REF! -> #REF! | D19: =IF('Residual-Rostered'!#REF!=0,"-",'Residual-Rostered'!#REF!) -> #REF! | E19: =IF('Residual-Rostered'!#REF!=0,"-",'Residual-Rostered'!#REF!) -> #REF! | F19: =IF('Residual-Rostered'!#REF!=0,"-",'Residual-Rostered'!#REF!) -> #REF! | G19: =IF('Residual-Rostered'!#REF!=0,"-",'Residual-Rostered'!#REF!) -> #REF! | H19: =IF('Residual-Rostered'!#REF!=0,"-",'Residual-Rostered'!#REF!) -> #REF! | I19: =IF('Residual-Rostered'!#REF!=0,"-",'Residual-Rostered'!#REF!) -> #REF! | J19: =IF('Residual-Rostered'!#REF!=0,"-",'Residual-Rostered'!#REF!) -> #REF! | K19: =IF('Residual-Rostered'!#REF!=0,"-",'Residual-Rostered'!#REF!) -> #REF! | ... AS19: =IF('Residual-Rostered'!#REF!=0,"-",'Residual-Rostered'!#REF!) -> #REF!
A20: ='Residual-Rostered'!#REF! -> #REF! | B20: ='Residual-Rostered'!#REF! -> #REF! | C20: ='Residual-Rostered'!#REF! -> #REF! | D20: =IF('Residual-Rostered'!#REF!=0,"-",'Residual-Rostered'!#REF!) -> #REF! | E20: =IF('Residual-Rostered'!#REF!=0,"-",'Residual-Rostered'!#REF!) -> #REF! | F20: =IF('Residual-Rostered'!#REF!=0,"-",'Residual-Rostered'!#REF!) -> #REF! | G20: =IF('Residual-Rostered'!#REF!=0,"-",'Residual-Rostered'!#REF!) -> #REF! | H20: =IF('Residual-Rostered'!#REF!=0,"-",'Residual-Rostered'!#REF!) -> #REF! | I20: =IF('Residual-Rostered'!#REF!=0,"-",'Residual-Rostered'!#REF!) -> #REF! | J20: =IF('Residual-Rostered'!#REF!=0,"-",'Residual-Rostered'!#REF!) -> #REF! | K20: =IF('Residual-Rostered'!#REF!=0,"-",'Residual-Rostered'!#REF!) -> #REF! | ... AS20: =IF('Residual-Rostered'!#REF!=0,"-",'Residual-Rostered'!#REF!) -> #REF!
A21: ='Residual-Rostered'!#REF! -> #REF! | B21: ='Residual-Rostered'!#REF! -> #REF! | C21: ='Residual-Rostered'!#REF! -> #REF! | D21: =IF('Residual-Rostered'!#REF!=0,"-",'Residual-Rostered'!#REF!) -> #REF! | E21: =IF('Residual-Rostered'!#REF!=0,"-",'Residual-Rostered'!#REF!) -> #REF! | F21: =IF('Residual-Rostered'!#REF!=0,"-",'Residual-Rostered'!#REF!) -> #REF! | G21: =IF('Residual-Rostered'!#REF!=0,"-",'Residual-Rostered'!#REF!) -> #REF! | H21: =IF('Residual-Rostered'!#REF!=0,"-",'Residual-Rostered'!#REF!) -> #REF! | I21: =IF('Residual-Rostered'!#REF!=0,"-",'Residual-Rostered'!#REF!) -> #REF! | J21: =IF('Residual-Rostered'!#REF!=0,"-",'Residual-Rostered'!#REF!) -> #REF! | K21: =IF('Residual-Rostered'!#REF!=0,"-",'Residual-Rostered'!#REF!) -> #REF! | ... AS21: =IF('Residual-Rostered'!#REF!=0,"-",'Residual-Rostered'!#REF!) -> #REF!
A22: ='Residual-Rostered'!#REF! -> #REF! | B22: ='Residual-Rostered'!#REF! -> #REF! | C22: ='Residual-Rostered'!#REF! -> #REF! | D22: =IF('Residual-Rostered'!#REF!=0,"-",'Residual-Rostered'!#REF!) -> #REF! | E22: =IF('Residual-Rostered'!#REF!=0,"-",'Residual-Rostered'!#REF!) -> #REF! | F22: =IF('Residual-Rostered'!#REF!=0,"-",'Residual-Rostered'!#REF!) -> #REF! | G22: =IF('Residual-Rostered'!#REF!=0,"-",'Residual-Rostered'!#REF!) -> #REF! | H22: =IF('Residual-Rostered'!#REF!=0,"-",'Residual-Rostered'!#REF!) -> #REF! | I22: =IF('Residual-Rostered'!#REF!=0,"-",'Residual-Rostered'!#REF!) -> #REF! | J22: =IF('Residual-Rostered'!#REF!=0,"-",'Residual-Rostered'!#REF!) -> #REF! | K22: =IF('Residual-Rostered'!#REF!=0,"-",'Residual-Rostered'!#REF!) -> #REF! | ... AS22: =IF('Residual-Rostered'!#REF!=0,"-",'Residual-Rostered'!#REF!) -> #REF!
A23: ='Residual-Rostered'!#REF! -> #REF! | B23: ='Residual-Rostered'!#REF! -> #REF! | C23: ='Residual-Rostered'!#REF! -> #REF! | D23: =IF('Residual-Rostered'!#REF!=0,"-",'Residual-Rostered'!#REF!) -> #REF! | E23: =IF('Residual-Rostered'!#REF!=0,"-",'Residual-Rostered'!#REF!) -> #REF! | F23: =IF('Residual-Rostered'!#REF!=0,"-",'Residual-Rostered'!#REF!) -> #REF! | G23: =IF('Residual-Rostered'!#REF!=0,"-",'Residual-Rostered'!#REF!) -> #REF! | H23: =IF('Residual-Rostered'!#REF!=0,"-",'Residual-Rostered'!#REF!) -> #REF! | I23: =IF('Residual-Rostered'!#REF!=0,"-",'Residual-Rostered'!#REF!) -> #REF! | J23: =IF('Residual-Rostered'!#REF!=0,"-",'Residual-Rostered'!#REF!) -> #REF! | K23: =IF('Residual-Rostered'!#REF!=0,"-",'Residual-Rostered'!#REF!) -> #REF! | ... AS23: =IF('Residual-Rostered'!#REF!=0,"-",'Residual-Rostered'!#REF!) -> #REF!
A24: ='Residual-Rostered'!#REF! -> #REF! | B24: ='Residual-Rostered'!#REF! -> #REF! | C24: ='Residual-Rostered'!#REF! -> #REF! | D24: =IF('Residual-Rostered'!#REF!=0,"-",'Residual-Rostered'!#REF!) -> #REF! | E24: =IF('Residual-Rostered'!#REF!=0,"-",'Residual-Rostered'!#REF!) -> #REF! | F24: =IF('Residual-Rostered'!#REF!=0,"-",'Residual-Rostered'!#REF!) -> #REF! | G24: =IF('Residual-Rostered'!#REF!=0,"-",'Residual-Rostered'!#REF!) -> #REF! | H24: =IF('Residual-Rostered'!#REF!=0,"-",'Residual-Rostered'!#REF!) -> #REF! | I24: =IF('Residual-Rostered'!#REF!=0,"-",'Residual-Rostered'!#REF!) -> #REF! | J24: =IF('Residual-Rostered'!#REF!=0,"-",'Residual-Rostered'!#REF!) -> #REF! | K24: =IF('Residual-Rostered'!#REF!=0,"-",'Residual-Rostered'!#REF!) -> #REF! | ... AS24: =IF('Residual-Rostered'!#REF!=0,"-",'Residual-Rostered'!#REF!) -> #REF!
... A62: ='Residual-Rostered'!#REF! -> #REF! | B62: ='Residual-Rostered'!#REF! -> #REF! | C62: ='Residual-Rostered'!#REF! -> #REF! | D62: =IF('Residual-Rostered'!#REF!=0,"-",'Residual-Rostered'!#REF!) -> #REF! | E62: =IF('Residual-Rostered'!#REF!=0,"-",'Residual-Rostered'!#REF!) -> #REF! | F62: =IF('Residual-Rostered'!#REF!=0,"-",'Residual-Rostered'!#REF!) -> #REF! | G62: =IF('Residual-Rostered'!#REF!=0,"-",'Residual-Rostered'!#REF!) -> #REF! | H62: =IF('Residual-Rostered'!#REF!=0,"-",'Residual-Rostered'!#REF!) -> #REF! | I62: =IF('Residual-Rostered'!#REF!=0,"-",'Residual-Rostered'!#REF!) -> #REF! | J62: =IF('Residual-Rostered'!#REF!=0,"-",'Residual-Rostered'!#REF!) -> #REF! | K62: =IF('Residual-Rostered'!#REF!=0,"-",'Residual-Rostered'!#REF!) -> #REF! | ... AS62: =IF('Residual-Rostered'!#REF!=0,"-",'Residual-Rostered'!#REF!) -> #REF!
I64: =I21 -> #REF!

Sheet FILEPATH
B1: MAIT date adjusted for example | C1: =F1-E1 -> 28 | E1: 45068 | F1: 45096 | J1: UNITS | K1: HRS/FTE
J2: HRS | K2: 1
J3: FTE | K3: 7.6
A4: SharedPath | B4: {=CELL("filename",E19)} -> C:\Users\Alex\CentriNOTSYNC\ResidentialCare\CLIENT\DATExx-Whiddon\2. Calculations\Change\SS\[ResidualAllocation-ALL.xlsx]FILEPATH
A6: Client | B6: {=[1]!Client} -> 04.1 PoC | C6: =FIND(B6,B4) -> #VALUE! | E6: =LEN(B6) -> 8 | J6: ROLE | L6: FACILITY
A7: Type | B7: 04 Analysis | C7: =FIND(B7,B4) -> #VALUE! | E7: =LEN(B7) -> 11 | J7: Carer | L7: Berry
A8: Settings Directory | B8: 2. Calculations | C8: =FIND(B8,B4) -> 67 | J8: Registered Nurse | L8: MAIT
C9: =C8-C7 -> #VALUE!
A11: This file | B11: Intervals.xlsx | C11: =FIND(B11,B4) -> #VALUE!
J12: FTE
B13: =MID(B4,C6+2+E6+E7,C9-E7-2) -> #VALUE!
B14: =LEFT(B13,6) -> #VALUE!
A15: Facility | C15: not required
A19: Settings.xlsx
A20: Location | B20: {=[1]!Computerpath} -> C:\Users\Alex\Centri\2. Accounts - 2.0 RFBI\04.1 PoC | C20: =LEN(B20) -> 52
C23: =SUM(C20:C22) -> 52
B26: =B20&"\" -> C:\Users\Alex\Centri\2. Accounts - 2.0 RFBI\04.1 PoC\
M28: Source1 = Excel.CurrentWorkbook(){[Name="Folder"]}[Content],
A29: Root Location | M29: Folder = Source1{0}[Folder],
M32: Source = Excel.Workbook(File.Contents(Folder & "
B35: Folder
B36: =B20&"\"&B7&"\"&B14&"\"&B15 -> #VALUE!

Sheet Carer
B1: Column1 | C1: Column2
B2: FACILITY: | C2: MAIT | K2: CHOOSE UNITS: | L2: HRS | M2: =_xlfn.XLOOKUP(Carer!L2,Table5[UNITS],Table5[HRS/FTE]) -> 1 | O2: Max HRS: | P2: 76
H3: Mon | K3: Tuesday | N3: Wednesday | Q3: Thursday | T3: Friday | W3: Saturday | Z3: Sunday | AC3: ` | AF3: T | AI3: W | AL3: T | AO3: F | AR3: S | AU3: S
A4: =Header!B10 -> Facility | B4: =Header!C10 -> EffortType | C4: =Header!D10 -> Role | D4: RN | H4: =Header!E10 -> 19/06 AM | I4: =Header!F10 -> 19/06 PM | J4: =Header!G10 -> 19/06 NIGHT | K4: =Header!H10 -> 20/06 AM | L4: =Header!I10 -> 20/06 PM | M4: =Header!J10 -> 20/06 NIGHT | N4: =Header!K10 -> 21/06 AM | O4: =Header!L10 -> 21/06 PM | ... AW4: =Header!AT10 -> 2/07 NIGHT
A5: =Header!B11 -> MAIT | B5: =SUM(H5:AW5) -> 2698.2 | G5: ='Header-RN'!B2 -> Demand | H5: ='Header-CARER'!D2 -> 84.8 | I5: ='Header-CARER'!E2 -> 68.3 | J5: ='Header-CARER'!F2 -> 37 | K5: ='Header-CARER'!G2 -> 87.5 | L5: ='Header-CARER'!H2 -> 68.3 | M5: ='Header-CARER'!I2 -> 37 | N5: ='Header-CARER'!J2 -> 87.5 | O5: ='Header-CARER'!K2 -> 68.3 | ... AW5: ='Header-CARER'!AS2 -> 37
A6: =Header!B12 -> MAIT | B6: =SUM(H6:AW6) -> 2455.1 | D6: Shortage | E6: Excess | G6: ='Header-RN'!B3 -> Allocation | H6: ='Header-CARER'!D3 -> 84.2 | I6: ='Header-CARER'!E3 -> 65.5 | J6: ='Header-CARER'!F3 -> 35.9 | K6: ='Header-CARER'!G3 -> 87.5 | L6: ='Header-CARER'!H3 -> 72.3 | M6: ='Header-CARER'!I3 -> 35.9 | N6: ='Header-CARER'!J3 -> 80.4 | O6: ='Header-CARER'!K3 -> 72.3 | ... AW6: ='Header-CARER'!AS3 -> 16
A7: =Header!B16 -> MAIT | D7: =SUM(H8:AW8) -> -263.5 | E7: =SUM(H9:AW9) -> 19.6 | G7: ='Header-RN'!B4 -> Initial DA Gap | H7: ='Header-CARER'!D4 -> -0.7 | I7: ='Header-CARER'!E4 -> -2.8 | J7: ='Header-CARER'!F4 -> -1.2 | K7: ='Header-CARER'!G4 -> 0 | L7: ='Header-CARER'!H4 -> 4 | M7: ='Header-CARER'!I4 -> -1.2 | N7: ='Header-CARER'!J4 -> -7.1 | O7: ='Header-CARER'!K4 -> 4 | ... AW7: ='Header-CARER'!AS4 -> -20.9
H8: =IF(H7<0,H7,"") -> -0.7 | I8: =IF(I7<0,I7,"") -> -2.8 | J8: =IF(J7<0,J7,"") -> -1.2 | K8: =IF(K7<0,K7,"") | L8: =IF(L7<0,L7,"") | M8: =IF(M7<0,M7,"") -> -1.2 | N8: =IF(N7<0,N7,"") -> -7.1 | O8: =IF(O7<0,O7,"") | ... AW8: =IF(AW7<0,AW7,"") -> -20.9
H9: =IF(H7>0,H7,"") | I9: =IF(I7>0,I7,"") | J9: =IF(J7>0,J7,"") | K9: =IF(K7>0,K7,"") | L9: =IF(L7>0,L7,"") -> 4 | M9: =IF(M7>0,M7,"") | N9: =IF(N7>0,N7,"") | O9: =IF(O7>0,O7,"") -> 4 | ... AW9: =IF(AW7>0,AW7,"")
G10: HeadCount
D11: =D7-D12 -> -106.2 | E11: =E7-E12 -> -15 | G11: Change | H11: =SUM(Table314[2])/UNIT -> 0 | I11: =SUM(Table314[3])/UNIT -> 3 | J11: =SUM(Table314[4])/UNIT -> 0 | K11: =SUM(Table314[5])/UNIT -> 0 | L11: =SUM(Table314[6])/UNIT -> -1.5 | M11: =SUM(Table314[7])/UNIT -> 0 | N11: =SUM(Table314[8])/UNIT -> 7.8 | O11: =SUM(Table314[9])/UNIT -> -8.8 | P11: =SUM(Table314[10])/UNIT -> 7.9 | Q11: =SUM(Table314[11])/UNIT -> 8.8 | R11: =SUM(Table314[12])/UNIT -> 0 | S11: =SUM(Table314[13])/UNIT -> 0 | T11: =SUM(Table314[14])/UNIT -> 23.4 | U11: =SUM(Table314[15])/UNIT -> 9.5 | V11: =SUM(Table314[16])/UNIT -> 0.5 | W11: =SUM(Table314[17])/UNIT -> 7.2 | X11: =SUM(Table314[18])/UNIT -> 0 | Y11: =SUM(Table314[19])/UNIT -> 0 | Z11: =SUM(Table314[20])/UNIT -> 7.2 | AA11: =SUM(Table314[21])/UNIT -> 0 | AB11: =SUM(Table314[22])/UNIT -> 0 | AC11: =SUM(Table314[23])/UNIT -> 0 | AD11: =SUM(Table314[24])/UNIT -> 0 | AE11: =SUM(Table314[25])/UNIT -> 0 | AF11: =SUM(Table314[26])/UNIT -> 0 | AG11: =SUM(Table314[27])/UNIT -> 0 | AH11: =SUM(Table314[28])/UNIT -> 0 | AI11: =SUM(Table314[29])/UNIT -> 7.8 | AJ11: =SUM(Table314[30])/UNIT -> 7.1 | AK11: =SUM(Table314[31])/UNIT -> 0.7 | AL11: =SUM(Table314[32])/UNIT -> 0 | AM11: =SUM(Table314[33])/UNIT -> 13.1 | AN11: =SUM(Table314[34])/UNIT -> 0 | AO11: =SUM(Table314[35])/UNIT -> 9.5 | AP11: =SUM(Table314[36])/UNIT -> 0 | AQ11: =SUM(Table314[37])/UNIT -> 0 | AR11: =SUM(Table314[38])/UNIT -> 10.6 | AS11: =SUM(Table314[39])/UNIT -> 0 | AT11: =SUM(Table314[40])/UNIT -> 0 | AU11: =SUM(Table314[41])/UNIT -> 7.4 | AV11: =SUM(Table314[42])/UNIT -> 0 | AW11: =SUM(Table314[43])/UNIT -> 0
D12: =SUM(H13:AW13) -> -157.3 | E12: =SUM(H14:AW14) -> 34.6 | G12: Remaining GAP | H12: =H7+H11 -> -0.7 | I12: =I7+I11 -> 0.2 | J12: =J7+J11 -> -1.2 | K12: =K7+K11 -> 0 | L12: =L7+L11 -> 2.5 | M12: =M7+M11 -> -1.2 | N12: =N7+N11 -> 0.7 | O12: =O7+O11 -> -4.8 | ... AW12: =AW7+AW11 -> -20.9
H13: =IF(H12<0,H12,"") -> -0.7 | I13: =IF(I12<0,I12,"") | J13: =IF(J12<0,J12,"") -> -1.2 | K13: =IF(K12<0,K12,"") | L13: =IF(L12<0,L12,"") | M13: =IF(M12<0,M12,"") -> -1.2 | N13: =IF(N12<0,N12,"") | O13: =IF(O12<0,O12,"") -> -4.8 | ... AW13: =IF(AW12<0,AW12,"") -> -20.9
H14: =IF(H12>0,H12,"") | I14: =IF(I12>0,I12,"") -> 0.2 | J14: =IF(J12>0,J12,"") | K14: =IF(K12>0,K12,"") | L14: =IF(L12>0,L12,"") -> 2.5 | M14: =IF(M12>0,M12,"") | N14: =IF(N12>0,N12,"") -> 0.7 | O14: =IF(O12>0,O12,"") | ... AW14: =IF(AW12>0,AW12,"")
B17: Role] | C17: NAME | D17: ROSTERED TIME | E17: RESIDUAL TIME | F17: CHANGE TIME | G17: CHANGED TOTAL | H17: 2 | I17: 3 | J17: 4 | K17: 5 | L17: 6 | M17: 7 | N17: 8 | O17: 9 | P17: 10 | Q17: 11 | R17: 12 | S17: 13 | T17: 14 | U17: 15 | V17: 16 | W17: 17 | X17: 18 | Y17: 19 | Z17: 20 | AA17: 21 | AB17: 22 | AC17: 23 | AD17: 24 | AE17: 25 | AF17: 26 | AG17: 27 | AH17: 28 | AI17: 29 | AJ17: 30 | AK17: 31 | AL17: 32 | AM17: 33 | AN17: 34 | AO17: 35 | AP17: 36 | AQ17: 37 | AR17: 38 | AS17: 39 | AT17: 40 | AU17: 41 | AV17: 42 | AW17: 43
A18: ='Residual-Rostered'!#REF! -> #REF! | B18: ='Residual-RosteredMATRIX-CARER'!D51 -> 0 | C18: ='Residual-RosteredMATRIX-CARER'!C51 -> 0 | D18: ='Residual-RosteredMATRIX-RN'!D51 -> 0 | E18: =Max_HRS-Table314[[#This Row],[ROSTERED TIME]] -> 76 | F18: =SUM(H18:AV18) -> 0 | G18: =Table314[[#This Row],[ROSTERED TIME]]+Table314[[#This Row],[CHANGE TIME]] -> 0 | H18: =IF('Residual-RosteredMATRIX-CARER'!F51=0,"",'Residual-RosteredMATRIX-CARER'!F51) | I18: =IF('Residual-RosteredMATRIX-CARER'!G51=0,"",'Residual-RosteredMATRIX-CARER'!G51) | J18: =IF('Residual-RosteredMATRIX-CARER'!H51=0,"",'Residual-RosteredMATRIX-CARER'!H51) | K18: =IF('Residual-RosteredMATRIX-CARER'!I51=0,"",'Residual-RosteredMATRIX-CARER'!I51) | L18: =IF('Residual-RosteredMATRIX-CARER'!J51=0,"",'Residual-RosteredMATRIX-CARER'!J51) | M18: =IF('Residual-RosteredMATRIX-CARER'!K51=0,"",'Residual-RosteredMATRIX-CARER'!K51) | N18: =IF('Residual-RosteredMATRIX-CARER'!L51=0,"",'Residual-RosteredMATRIX-CARER'!L51) | O18: =IF('Residual-RosteredMATRIX-CARER'!M51=0,"",'Residual-RosteredMATRIX-CARER'!M51) | ... AW18: =IF('Residual-RosteredMATRIX-CARER'!AU51=0,"",'Residual-RosteredMATRIX-CARER'!AU51)
A19: ='Residual-Rostered'!#REF! -> #REF! | B19: ='Residual-RosteredMATRIX-CARER'!D52 -> 0 | C19: ='Residual-RosteredMATRIX-CARER'!C52 -> 0 | D19: ='Residual-RosteredMATRIX-RN'!D52 -> 0 | E19: =Max_HRS-Table314[[#This Row],[ROSTERED TIME]] -> 76 | F19: =SUM(H19:AV19) -> 0 | G19: =Table314[[#This Row],[ROSTERED TIME]]+Table314[[#This Row],[CHANGE TIME]] -> 0 | H19: =IF('Residual-RosteredMATRIX-CARER'!F52=0,"",'Residual-RosteredMATRIX-CARER'!F52) | I19: =IF('Residual-RosteredMATRIX-CARER'!G52=0,"",'Residual-RosteredMATRIX-CARER'!G52) | J19: =IF('Residual-RosteredMATRIX-CARER'!H52=0,"",'Residual-RosteredMATRIX-CARER'!H52) | K19: =IF('Residual-RosteredMATRIX-CARER'!I52=0,"",'Residual-RosteredMATRIX-CARER'!I52) | L19: =IF('Residual-RosteredMATRIX-CARER'!J52=0,"",'Residual-RosteredMATRIX-CARER'!J52) | M19: =IF('Residual-RosteredMATRIX-CARER'!K52=0,"",'Residual-RosteredMATRIX-CARER'!K52) | N19: =IF('Residual-RosteredMATRIX-CARER'!L52=0,"",'Residual-RosteredMATRIX-CARER'!L52) | O19: =IF('Residual-RosteredMATRIX-CARER'!M52=0,"",'Residual-RosteredMATRIX-CARER'!M52) | ... AW19: =IF('Residual-RosteredMATRIX-CARER'!AU52=0,"",'Residual-RosteredMATRIX-CARER'!AU52)
A20: ='Residual-Rostered'!#REF! -> #REF! | B20: ='Residual-RosteredMATRIX-CARER'!D53 -> 0 | C20: ='Residual-RosteredMATRIX-CARER'!C53 -> 0 | D20: ='Residual-RosteredMATRIX-RN'!D53 -> 0 | E20: =Max_HRS-Table314[[#This Row],[ROSTERED TIME]] -> 76 | F20: =SUM(H20:AV20) -> 0 | G20: =Table314[[#This Row],[ROSTERED TIME]]+Table314[[#This Row],[CHANGE TIME]] -> 0 | H20: =IF('Residual-RosteredMATRIX-CARER'!F53=0,"",'Residual-RosteredMATRIX-CARER'!F53) | I20: =IF('Residual-RosteredMATRIX-CARER'!G53=0,"",'Residual-RosteredMATRIX-CARER'!G53) | J20: =IF('Residual-RosteredMATRIX-CARER'!H53=0,"",'Residual-RosteredMATRIX-CARER'!H53) | K20: =IF('Residual-RosteredMATRIX-CARER'!I53=0,"",'Residual-RosteredMATRIX-CARER'!I53) | L20: =IF('Residual-RosteredMATRIX-CARER'!J53=0,"",'Residual-RosteredMATRIX-CARER'!J53) | M20: =IF('Residual-RosteredMATRIX-CARER'!K53=0,"",'Residual-RosteredMATRIX-CARER'!K53) | N20: =IF('Residual-RosteredMATRIX-CARER'!L53=0,"",'Residual-RosteredMATRIX-CARER'!L53) | O20: =IF('Residual-RosteredMATRIX-CARER'!M53=0,"",'Residual-RosteredMATRIX-CARER'!M53) | ... AW20: =IF('Residual-RosteredMATRIX-CARER'!AU53=0,"",'Residual-RosteredMATRIX-CARER'!AU53)
A21: ='Residual-Rostered'!#REF! -> #REF! | B21: ='Residual-RosteredMATRIX-CARER'!D54 -> 0 | C21: ='Residual-RosteredMATRIX-CARER'!C54 -> 0 | D21: ='Residual-RosteredMATRIX-RN'!D54 -> 0 | E21: =Max_HRS-Table314[[#This Row],[ROSTERED TIME]] -> 76 | F21: =SUM(H21:AV21) -> 0 | G21: =Table314[[#This Row],[ROSTERED TIME]]+Table314[[#This Row],[CHANGE TIME]] -> 0 | H21: =IF('Residual-RosteredMATRIX-CARER'!F54=0,"",'Residual-RosteredMATRIX-CARER'!F54) | I21: =IF('Residual-RosteredMATRIX-CARER'!G54=0,"",'Residual-RosteredMATRIX-CARER'!G54) | J21: =IF('Residual-RosteredMATRIX-CARER'!H54=0,"",'Residual-RosteredMATRIX-CARER'!H54) | K21: =IF('Residual-RosteredMATRIX-CARER'!I54=0,"",'Residual-RosteredMATRIX-CARER'!I54) | L21: =IF('Residual-RosteredMATRIX-CARER'!J54=0,"",'Residual-RosteredMATRIX-CARER'!J54) | M21: =IF('Residual-RosteredMATRIX-CARER'!K54=0,"",'Residual-RosteredMATRIX-CARER'!K54) | N21: =IF('Residual-RosteredMATRIX-CARER'!L54=0,"",'Residual-RosteredMATRIX-CARER'!L54) | O21: =IF('Residual-RosteredMATRIX-CARER'!M54=0,"",'Residual-RosteredMATRIX-CARER'!M54) | ... AW21: =IF('Residual-RosteredMATRIX-CARER'!AU54=0,"",'Residual-RosteredMATRIX-CARER'!AU54)
A22: ='Residual-Rostered'!#REF! -> #REF! | B22: ='Residual-RosteredMATRIX-CARER'!D55 -> 0 | C22: ='Residual-RosteredMATRIX-CARER'!C55 -> 0 | D22: ='Residual-RosteredMATRIX-RN'!D55 -> 0 | E22: =Max_HRS-Table314[[#This Row],[ROSTERED TIME]] -> 76 | F22: =SUM(H22:AV22) -> 0 | G22: =Table314[[#This Row],[ROSTERED TIME]]+Table314[[#This Row],[CHANGE TIME]] -> 0 | H22: =IF('Residual-RosteredMATRIX-CARER'!F55=0,"",'Residual-RosteredMATRIX-CARER'!F55) | I22: =IF('Residual-RosteredMATRIX-CARER'!G55=0,"",'Residual-RosteredMATRIX-CARER'!G55) | J22: =IF('Residual-RosteredMATRIX-CARER'!H55=0,"",'Residual-RosteredMATRIX-CARER'!H55) | K22: =IF('Residual-RosteredMATRIX-CARER'!I55=0,"",'Residual-RosteredMATRIX-CARER'!I55) | L22: =IF('Residual-RosteredMATRIX-CARER'!J55=0,"",'Residual-RosteredMATRIX-CARER'!J55) | M22: =IF('Residual-RosteredMATRIX-CARER'!K55=0,"",'Residual-RosteredMATRIX-CARER'!K55) | N22: =IF('Residual-RosteredMATRIX-CARER'!L55=0,"",'Residual-RosteredMATRIX-CARER'!L55) | O22: =IF('Residual-RosteredMATRIX-CARER'!M55=0,"",'Residual-RosteredMATRIX-CARER'!M55) | ... AW22: =IF('Residual-RosteredMATRIX-CARER'!AU55=0,"",'Residual-RosteredMATRIX-CARER'!AU55)
A23: ='Residual-Rostered'!#REF! -> #REF! | B23: ='Residual-RosteredMATRIX-CARER'!D56 -> 0 | C23: ='Residual-RosteredMATRIX-CARER'!C56 -> 0 | D23: ='Residual-RosteredMATRIX-RN'!D56 -> 0 | E23: =Max_HRS-Table314[[#This Row],[ROSTERED TIME]] -> 76 | F23: =SUM(H23:AV23) -> 0 | G23: =Table314[[#This Row],[ROSTERED TIME]]+Table314[[#This Row],[CHANGE TIME]] -> 0 | H23: =IF('Residual-RosteredMATRIX-CARER'!F56=0,"",'Residual-RosteredMATRIX-CARER'!F56) | I23: =IF('Residual-RosteredMATRIX-CARER'!G56=0,"",'Residual-RosteredMATRIX-CARER'!G56) | J23: =IF('Residual-RosteredMATRIX-CARER'!H56=0,"",'Residual-RosteredMATRIX-CARER'!H56) | K23: =IF('Residual-RosteredMATRIX-CARER'!I56=0,"",'Residual-RosteredMATRIX-CARER'!I56) | L23: =IF('Residual-RosteredMATRIX-CARER'!J56=0,"",'Residual-RosteredMATRIX-CARER'!J56) | M23: =IF('Residual-RosteredMATRIX-CARER'!K56=0,"",'Residual-RosteredMATRIX-CARER'!K56) | N23: =IF('Residual-RosteredMATRIX-CARER'!L56=0,"",'Residual-RosteredMATRIX-CARER'!L56) | O23: =IF('Residual-RosteredMATRIX-CARER'!M56=0,"",'Residual-RosteredMATRIX-CARER'!M56) | ... AW23: =IF('Residual-RosteredMATRIX-CARER'!AU56=0,"",'Residual-RosteredMATRIX-CARER'!AU56)
A24: ='Residual-Rostered'!#REF! -> #REF! | B24: ='Residual-RosteredMATRIX-CARER'!D57 -> 0 | C24: ='Residual-RosteredMATRIX-CARER'!C57 -> 0 | D24: ='Residual-RosteredMATRIX-RN'!D57 -> 0 | E24: =Max_HRS-Table314[[#This Row],[ROSTERED TIME]] -> 76 | F24: =SUM(H24:AV24) -> 0 | G24: =Table314[[#This Row],[ROSTERED TIME]]+Table314[[#This Row],[CHANGE TIME]] -> 0 | H24: =IF('Residual-RosteredMATRIX-CARER'!F57=0,"",'Residual-RosteredMATRIX-CARER'!F57) | I24: =IF('Residual-RosteredMATRIX-CARER'!G57=0,"",'Residual-RosteredMATRIX-CARER'!G57) | J24: =IF('Residual-RosteredMATRIX-CARER'!H57=0,"",'Residual-RosteredMATRIX-CARER'!H57) | K24: =IF('Residual-RosteredMATRIX-CARER'!I57=0,"",'Residual-RosteredMATRIX-CARER'!I57) | L24: =IF('Residual-RosteredMATRIX-CARER'!J57=0,"",'Residual-RosteredMATRIX-CARER'!J57) | M24: =IF('Residual-RosteredMATRIX-CARER'!K57=0,"",'Residual-RosteredMATRIX-CARER'!K57) | N24: =IF('Residual-RosteredMATRIX-CARER'!L57=0,"",'Residual-RosteredMATRIX-CARER'!L57) | O24: =IF('Residual-RosteredMATRIX-CARER'!M57=0,"",'Residual-RosteredMATRIX-CARER'!M57) | ... AW24: =IF('Residual-RosteredMATRIX-CARER'!AU57=0,"",'Residual-RosteredMATRIX-CARER'!AU57)
A25: ='Residual-Rostered'!#REF! -> #REF! | B25: ='Residual-RosteredMATRIX-CARER'!D58 -> 0 | C25: ='Residual-RosteredMATRIX-CARER'!C58 -> 0 | D25: ='Residual-RosteredMATRIX-RN'!D58 -> 0 | E25: =Max_HRS-Table314[[#This Row],[ROSTERED TIME]] -> 76 | F25: =SUM(H25:AV25) -> 0 | G25: =Table314[[#This Row],[ROSTERED TIME]]+Table314[[#This Row],[CHANGE TIME]] -> 0 | H25: =IF('Residual-RosteredMATRIX-CARER'!F58=0,"",'Residual-RosteredMATRIX-CARER'!F58) | I25: =IF('Residual-RosteredMATRIX-CARER'!G58=0,"",'Residual-RosteredMATRIX-CARER'!G58) | J25: =IF('Residual-RosteredMATRIX-CARER'!H58=0,"",'Residual-RosteredMATRIX-CARER'!H58) | K25: =IF('Residual-RosteredMATRIX-CARER'!I58=0,"",'Residual-RosteredMATRIX-CARER'!I58) | L25: =IF('Residual-RosteredMATRIX-CARER'!J58=0,"",'Residual-RosteredMATRIX-CARER'!J58) | M25: =IF('Residual-RosteredMATRIX-CARER'!K58=0,"",'Residual-RosteredMATRIX-CARER'!K58) | N25: =IF('Residual-RosteredMATRIX-CARER'!L58=0,"",'Residual-RosteredMATRIX-CARER'!L58) | O25: =IF('Residual-RosteredMATRIX-CARER'!M58=0,"",'Residual-RosteredMATRIX-CARER'!M58) | ... AW25: =IF('Residual-RosteredMATRIX-CARER'!AU58=0,"",'Residual-RosteredMATRIX-CARER'!AU58)
A26: ='Residual-Rostered'!#REF! -> #REF! | B26: ='Residual-RosteredMATRIX-CARER'!D59 -> 0 | C26: ='Residual-RosteredMATRIX-CARER'!C59 -> 0 | D26: ='Residual-RosteredMATRIX-RN'!D59 -> 0 | E26: =Max_HRS-Table314[[#This Row],[ROSTERED TIME]] -> 76 | F26: =SUM(H26:AV26) -> 0 | G26: =Table314[[#This Row],[ROSTERED TIME]]+Table314[[#This Row],[CHANGE TIME]] -> 0 | H26: =IF('Residual-RosteredMATRIX-CARER'!F59=0,"",'Residual-RosteredMATRIX-CARER'!F59) | I26: =IF('Residual-RosteredMATRIX-CARER'!G59=0,"",'Residual-RosteredMATRIX-CARER'!G59) | J26: =IF('Residual-RosteredMATRIX-CARER'!H59=0,"",'Residual-RosteredMATRIX-CARER'!H59) | K26: =IF('Residual-RosteredMATRIX-CARER'!I59=0,"",'Residual-RosteredMATRIX-CARER'!I59) | L26: =IF('Residual-RosteredMATRIX-CARER'!J59=0,"",'Residual-RosteredMATRIX-CARER'!J59) | M26: =IF('Residual-RosteredMATRIX-CARER'!K59=0,"",'Residual-RosteredMATRIX-CARER'!K59) | N26: =IF('Residual-RosteredMATRIX-CARER'!L59=0,"",'Residual-RosteredMATRIX-CARER'!L59) | O26: =IF('Residual-RosteredMATRIX-CARER'!M59=0,"",'Residual-RosteredMATRIX-CARER'!M59) | ... AW26: =IF('Residual-RosteredMATRIX-CARER'!AU59=0,"",'Residual-RosteredMATRIX-CARER'!AU59)
A27: ='Residual-Rostered'!#REF! -> #REF! | B27: ='Residual-RosteredMATRIX-CARER'!D60 -> 0 | C27: ='Residual-RosteredMATRIX-CARER'!C60 -> 0 | D27: ='Residual-RosteredMATRIX-RN'!D60 -> 0 | E27: =Max_HRS-Table314[[#This Row],[ROSTERED TIME]] -> 76 | F27: =SUM(H27:AV27) -> 0 | G27: =Table314[[#This Row],[ROSTERED TIME]]+Table314[[#This Row],[CHANGE TIME]] -> 0 | H27: =IF('Residual-RosteredMATRIX-CARER'!F60=0,"",'Residual-RosteredMATRIX-CARER'!F60) | I27: =IF('Residual-RosteredMATRIX-CARER'!G60=0,"",'Residual-RosteredMATRIX-CARER'!G60) | J27: =IF('Residual-RosteredMATRIX-CARER'!H60=0,"",'Residual-RosteredMATRIX-CARER'!H60) | K27: =IF('Residual-RosteredMATRIX-CARER'!I60=0,"",'Residual-RosteredMATRIX-CARER'!I60) | L27: =IF('Residual-RosteredMATRIX-CARER'!J60=0,"",'Residual-RosteredMATRIX-CARER'!J60) | M27: =IF('Residual-RosteredMATRIX-CARER'!K60=0,"",'Residual-RosteredMATRIX-CARER'!K60) | N27: =IF('Residual-RosteredMATRIX-CARER'!L60=0,"",'Residual-RosteredMATRIX-CARER'!L60) | O27: =IF('Residual-RosteredMATRIX-CARER'!M60=0,"",'Residual-RosteredMATRIX-CARER'!M60) | ... AW27: =IF('Residual-RosteredMATRIX-CARER'!AU60=0,"",'Residual-RosteredMATRIX-CARER'!AU60)
A28: ='Residual-Rostered'!#REF! -> #REF! | B28: ='Residual-RosteredMATRIX-CARER'!D61 -> 0 | C28: ='Residual-RosteredMATRIX-CARER'!C61 -> 0 | D28: ='Residual-RosteredMATRIX-RN'!D61 -> 0 | E28: =Max_HRS-Table314[[#This Row],[ROSTERED TIME]] -> 76 | F28: =SUM(H28:AV28) -> 0 | G28: =Table314[[#This Row],[ROSTERED TIME]]+Table314[[#This Row],[CHANGE TIME]] -> 0 | H28: =IF('Residual-RosteredMATRIX-CARER'!F61=0,"",'Residual-RosteredMATRIX-CARER'!F61) | I28: =IF('Residual-RosteredMATRIX-CARER'!G61=0,"",'Residual-RosteredMATRIX-CARER'!G61) | J28: =IF('Residual-RosteredMATRIX-CARER'!H61=0,"",'Residual-RosteredMATRIX-CARER'!H61) | K28: =IF('Residual-RosteredMATRIX-CARER'!I61=0,"",'Residual-RosteredMATRIX-CARER'!I61) | L28: =IF('Residual-RosteredMATRIX-CARER'!J61=0,"",'Residual-RosteredMATRIX-CARER'!J61) | M28: =IF('Residual-RosteredMATRIX-CARER'!K61=0,"",'Residual-RosteredMATRIX-CARER'!K61) | N28: =IF('Residual-RosteredMATRIX-CARER'!L61=0,"",'Residual-RosteredMATRIX-CARER'!L61) | O28: =IF('Residual-RosteredMATRIX-CARER'!M61=0,"",'Residual-RosteredMATRIX-CARER'!M61) | ... AW28: =IF('Residual-RosteredMATRIX-CARER'!AU61=0,"",'Residual-RosteredMATRIX-CARER'!AU61)
A29: ='Residual-Rostered'!#REF! -> #REF! | B29: ='Residual-RosteredMATRIX-CARER'!D62 -> 0 | C29: ='Residual-RosteredMATRIX-CARER'!C62 -> 0 | D29: ='Residual-RosteredMATRIX-RN'!D62 -> 0 | E29: =Max_HRS-Table314[[#This Row],[ROSTERED TIME]] -> 76 | F29: =SUM(H29:AV29) -> 0 | G29: =Table314[[#This Row],[ROSTERED TIME]]+Table314[[#This Row],[CHANGE TIME]] -> 0 | H29: =IF('Residual-RosteredMATRIX-CARER'!F62=0,"",'Residual-RosteredMATRIX-CARER'!F62) | I29: =IF('Residual-RosteredMATRIX-CARER'!G62=0,"",'Residual-RosteredMATRIX-CARER'!G62) | J29: =IF('Residual-RosteredMATRIX-CARER'!H62=0,"",'Residual-RosteredMATRIX-CARER'!H62) | K29: =IF('Residual-RosteredMATRIX-CARER'!I62=0,"",'Residual-RosteredMATRIX-CARER'!I62) | L29: =IF('Residual-RosteredMATRIX-CARER'!J62=0,"",'Residual-RosteredMATRIX-CARER'!J62) | M29: =IF('Residual-RosteredMATRIX-CARER'!K62=0,"",'Residual-RosteredMATRIX-CARER'!K62) | N29: =IF('Residual-RosteredMATRIX-CARER'!L62=0,"",'Residual-RosteredMATRIX-CARER'!L62) | O29: =IF('Residual-RosteredMATRIX-CARER'!M62=0,"",'Residual-RosteredMATRIX-CARER'!M62) | ... AW29: =IF('Residual-RosteredMATRIX-CARER'!AU62=0,"",'Residual-RosteredMATRIX-CARER'!AU62)
A30: ='Residual-Rostered'!#REF! -> #REF! | B30: ='Residual-RosteredMATRIX-CARER'!D63 -> 0 | C30: ='Residual-RosteredMATRIX-CARER'!C63 -> 0 | D30: ='Residual-RosteredMATRIX-RN'!D63 -> 0 | E30: =Max_HRS-Table314[[#This Row],[ROSTERED TIME]] -> 76 | F30: =SUM(H30:AV30) -> 0 | G30: =Table314[[#This Row],[ROSTERED TIME]]+Table314[[#This Row],[CHANGE TIME]] -> 0 | H30: =IF('Residual-RosteredMATRIX-RN'!E63=0,"",'Residual-RosteredMATRIX-RN'!E63) | I30: =IF('Residual-RosteredMATRIX-RN'!F63=0,"",'Residual-RosteredMATRIX-RN'!F63) | J30: =IF('Residual-RosteredMATRIX-RN'!G63=0,"",'Residual-RosteredMATRIX-RN'!G63) | K30: =IF('Residual-RosteredMATRIX-RN'!H63=0,"",'Residual-RosteredMATRIX-RN'!H63) | L30: =IF('Residual-RosteredMATRIX-RN'!I63=0,"",'Residual-RosteredMATRIX-RN'!I63) | M30: =IF('Residual-RosteredMATRIX-RN'!J63=0,"",'Residual-RosteredMATRIX-RN'!J63) | N30: =IF('Residual-RosteredMATRIX-RN'!K63=0,"",'Residual-RosteredMATRIX-RN'!K63) | O30: =IF('Residual-RosteredMATRIX-RN'!L63=0,"",'Residual-RosteredMATRIX-RN'!L63) | ... AW30: =IF('Residual-RosteredMATRIX-RN'!AT63=0,"",'Residual-RosteredMATRIX-RN'!AT63)
A31: ='Residual-Rostered'!#REF! -> #REF! | B31: ='Residual-RosteredMATRIX-CARER'!D64 -> 0 | C31: ='Residual-RosteredMATRIX-CARER'!C64 -> 0 | D31: ='Residual-RosteredMATRIX-RN'!D64 -> 0 | E31: =Max_HRS-Table314[[#This Row],[ROSTERED TIME]] -> 76 | F31: =SUM(H31:AV31) -> 0 | G31: =Table314[[#This Row],[ROSTERED TIME]]+Table314[[#This Row],[CHANGE TIME]] -> 0 | H31: =IF('Residual-RosteredMATRIX-RN'!E64=0,"",'Residual-RosteredMATRIX-RN'!E64) | I31: =IF('Residual-RosteredMATRIX-RN'!F64=0,"",'Residual-RosteredMATRIX-RN'!F64) | J31: =IF('Residual-RosteredMATRIX-RN'!G64=0,"",'Residual-RosteredMATRIX-RN'!G64) | K31: =IF('Residual-RosteredMATRIX-RN'!H64=0,"",'Residual-RosteredMATRIX-RN'!H64) | L31: =IF('Residual-RosteredMATRIX-RN'!I64=0,"",'Residual-RosteredMATRIX-RN'!I64) | M31: =IF('Residual-RosteredMATRIX-RN'!J64=0,"",'Residual-RosteredMATRIX-RN'!J64) | N31: =IF('Residual-RosteredMATRIX-RN'!K64=0,"",'Residual-RosteredMATRIX-RN'!K64) | O31: =IF('Residual-RosteredMATRIX-RN'!L64=0,"",'Residual-RosteredMATRIX-RN'!L64) | ... AW31: =IF('Residual-RosteredMATRIX-RN'!AT64=0,"",'Residual-RosteredMATRIX-RN'!AT64)
A32: ='Residual-Rostered'!#REF! -> #REF! | B32: ='Residual-RosteredMATRIX-CARER'!D65 -> 0 | C32: ='Residual-RosteredMATRIX-CARER'!C65 -> 0 | D32: ='Residual-RosteredMATRIX-RN'!D65 -> 0 | E32: =Max_HRS-Table314[[#This Row],[ROSTERED TIME]] -> 76 | F32: =SUM(H32:AV32) -> 0 | G32: =Table314[[#This Row],[ROSTERED TIME]]+Table314[[#This Row],[CHANGE TIME]] -> 0 | H32: =IF('Residual-RosteredMATRIX-RN'!E65=0,"",'Residual-RosteredMATRIX-RN'!E65) | I32: =IF('Residual-RosteredMATRIX-RN'!F65=0,"",'Residual-RosteredMATRIX-RN'!F65) | J32: =IF('Residual-RosteredMATRIX-RN'!G65=0,"",'Residual-RosteredMATRIX-RN'!G65) | K32: =IF('Residual-RosteredMATRIX-RN'!H65=0,"",'Residual-RosteredMATRIX-RN'!H65) | L32: =IF('Residual-RosteredMATRIX-RN'!I65=0,"",'Residual-RosteredMATRIX-RN'!I65) | M32: =IF('Residual-RosteredMATRIX-RN'!J65=0,"",'Residual-RosteredMATRIX-RN'!J65) | N32: =IF('Residual-RosteredMATRIX-RN'!K65=0,"",'Residual-RosteredMATRIX-RN'!K65) | O32: =IF('Residual-RosteredMATRIX-RN'!L65=0,"",'Residual-RosteredMATRIX-RN'!L65) | ... AW32: =IF('Residual-RosteredMATRIX-RN'!AT65=0,"",'Residual-RosteredMATRIX-RN'!AT65)
A33: ='Residual-Rostered'!#REF! -> #REF! | B33: ='Residual-RosteredMATRIX-CARER'!D66 -> 0 | C33: ='Residual-RosteredMATRIX-CARER'!C66 -> 0 | D33: ='Residual-RosteredMATRIX-RN'!D66 -> 0 | E33: =Max_HRS-Table314[[#This Row],[ROSTERED TIME]] -> 76 | F33: =SUM(H33:AV33) -> 0 | G33: =Table314[[#This Row],[ROSTERED TIME]]+Table314[[#This Row],[CHANGE TIME]] -> 0 | H33: =IF('Residual-RosteredMATRIX-RN'!E66=0,"",'Residual-RosteredMATRIX-RN'!E66) | I33: =IF('Residual-RosteredMATRIX-RN'!F66=0,"",'Residual-RosteredMATRIX-RN'!F66) | J33: =IF('Residual-RosteredMATRIX-RN'!G66=0,"",'Residual-RosteredMATRIX-RN'!G66) | K33: =IF('Residual-RosteredMATRIX-RN'!H66=0,"",'Residual-RosteredMATRIX-RN'!H66) | L33: =IF('Residual-RosteredMATRIX-RN'!I66=0,"",'Residual-RosteredMATRIX-RN'!I66) | M33: =IF('Residual-RosteredMATRIX-RN'!J66=0,"",'Residual-RosteredMATRIX-RN'!J66) | N33: =IF('Residual-RosteredMATRIX-RN'!K66=0,"",'Residual-RosteredMATRIX-RN'!K66) | O33: =IF('Residual-RosteredMATRIX-RN'!L66=0,"",'Residual-RosteredMATRIX-RN'!L66) | ... AW33: =IF('Residual-RosteredMATRIX-RN'!AT66=0,"",'Residual-RosteredMATRIX-RN'!AT66)
A34: ='Residual-Rostered'!#REF! -> #REF! | B34: ='Residual-RosteredMATRIX-CARER'!D2 -> Carer | C34: ='Residual-RosteredMATRIX-CARER'!C2 -> Anderson, Laura | D34: ='Residual-RosteredMATRIX-CARER'!E2 -> 59.5 | E34: =Max_HRS-Table314[[#This Row],[ROSTERED TIME]] -> 16.5 | F34: =SUM(H34:AV34) -> 8.1 | G34: =Table314[[#This Row],[ROSTERED TIME]]+Table314[[#This Row],[CHANGE TIME]] -> 67.6 | H34: =IF('Residual-RosteredMATRIX-CARER'!F2=0,"",'Residual-RosteredMATRIX-CARER'!F2) | I34: 1 | J34: =IF('Residual-RosteredMATRIX-CARER'!H2=0,"",'Residual-RosteredMATRIX-CARER'!H2) | K34: =IF('Residual-RosteredMATRIX-CARER'!I2=0,"",'Residual-RosteredMATRIX-CARER'!I2) | L34: =IF('Residual-RosteredMATRIX-CARER'!J2=0,"",'Residual-RosteredMATRIX-CARER'!J2) -> 1/ 7 | M34: =IF('Residual-RosteredMATRIX-CARER'!K2=0,"",'Residual-RosteredMATRIX-CARER'!K2) | N34: =IF('Residual-RosteredMATRIX-CARER'!L2=0,"",'Residual-RosteredMATRIX-CARER'!L2) | P34: =IF('Residual-RosteredMATRIX-CARER'!N2=0,"",'Residual-RosteredMATRIX-CARER'!N2) | Q34: =IF('Residual-RosteredMATRIX-CARER'!O2=0,"",'Residual-RosteredMATRIX-CARER'!O2) | R34: =IF('Residual-RosteredMATRIX-CARER'!P2=0,"",'Residual-RosteredMATRIX-CARER'!P2) -> 1/ 7 | S34: =IF('Residual-RosteredMATRIX-CARER'!Q2=0,"",'Residual-RosteredMATRIX-CARER'!Q2) | T34: =IF('Residual-RosteredMATRIX-CARER'!R2=0,"",'Residual-RosteredMATRIX-CARER'!R2) | U34: =IF('Residual-RosteredMATRIX-CARER'!S2=0,"",'Residual-RosteredMATRIX-CARER'!S2) | V34: =IF('Residual-RosteredMATRIX-CARER'!T2=0,"",'Residual-RosteredMATRIX-CARER'!T2) | W34: =IF('Residual-RosteredMATRIX-CARER'!U2=0,"",'Residual-RosteredMATRIX-CARER'!U2) | ... AI34: =IF('Residual-RosteredMATRIX-CARER'!AG2=0,"",'Residual-RosteredMATRIX-CARER'!AG2) | AJ34: 7.1 | AK34: =IF('Residual-RosteredMATRIX-CARER'!AI2=0,"",'Residual-RosteredMATRIX-CARER'!AI2) | AL34: =IF('Residual-RosteredMATRIX-CARER'!AJ2=0,"",'Residual-RosteredMATRIX-CARER'!AJ2) | AM34: =IF('Residual-RosteredMATRIX-CARER'!AK2=0,"",'Residual-RosteredMATRIX-CARER'!AK2) | AN34: =IF('Residual-RosteredMATRIX-CARER'!AL2=0,"",'Residual-RosteredMATRIX-CARER'!AL2) | AP34: =IF('Residual-RosteredMATRIX-CARER'!AN2=0,"",'Residual-RosteredMATRIX-CARER'!AN2) | AQ34: =IF('Residual-RosteredMATRIX-CARER'!AO2=0,"",'Residual-RosteredMATRIX-CARER'!AO2) | AR34: =IF('Residual-RosteredMATRIX-CARER'!AP2=0,"",'Residual-RosteredMATRIX-CARER'!AP2) -> 0.5/ 7.5 | AS34: =IF('Residual-RosteredMATRIX-CARER'!AQ2=0,"",'Residual-RosteredMATRIX-CARER'!AQ2) | AT34: =IF('Residual-RosteredMATRIX-CARER'!AR2=0,"",'Residual-RosteredMATRIX-CARER'!AR2) | AU34: =IF('Residual-RosteredMATRIX-CARER'!AS2=0,"",'Residual-RosteredMATRIX-CARER'!AS2) -> 0.5/ 7.5 | AV34: =IF('Residual-RosteredMATRIX-CARER'!AT2=0,"",'Residual-RosteredMATRIX-CARER'!AT2) | AW34: =IF('Residual-RosteredMATRIX-CARER'!AU2=0,"",'Residual-RosteredMATRIX-CARER'!AU2)
A35: ='Residual-Rostered'!#REF! -> #REF! | B35: ='Residual-RosteredMATRIX-CARER'!D4 -> Carer | C35: ='Residual-RosteredMATRIX-CARER'!C4 -> Anscombe, Misty | D35: ='Residual-RosteredMATRIX-CARER'!E4 -> 54.5 | E35: =Max_HRS-Table314[[#This Row],[ROSTERED TIME]] -> 21.5 | F35: =SUM(H35:AV35) -> 0 | G35: =Table314[[#This Row],[ROSTERED TIME]]+Table314[[#This Row],[CHANGE TIME]] -> 54.5 | H35: =IF('Residual-RosteredMATRIX-CARER'!F4=0,"",'Residual-RosteredMATRIX-CARER'!F4) | I35: =IF('Residual-RosteredMATRIX-CARER'!G4=0,"",'Residual-RosteredMATRIX-CARER'!G4) | J35: =IF('Residual-RosteredMATRIX-CARER'!H4=0,"",'Residual-RosteredMATRIX-CARER'!H4) | K35: =IF('Residual-RosteredMATRIX-CARER'!I4=0,"",'Residual-RosteredMATRIX-CARER'!I4) | L35: =IF('Residual-RosteredMATRIX-CARER'!J4=0,"",'Residual-RosteredMATRIX-CARER'!J4) | M35: =IF('Residual-RosteredMATRIX-CARER'!K4=0,"",'Residual-RosteredMATRIX-CARER'!K4) | N35: =IF('Residual-RosteredMATRIX-CARER'!L4=0,"",'Residual-RosteredMATRIX-CARER'!L4) | O35: =IF('Residual-RosteredMATRIX-CARER'!M4=0,"",'Residual-RosteredMATRIX-CARER'!M4) -> 0/ 7.8 | ... AW35: =IF('Residual-RosteredMATRIX-CARER'!AU4=0,"",'Residual-RosteredMATRIX-CARER'!AU4) -> 0/ 0.2
A36: ='Residual-Rostered'!#REF! -> #REF! | B36: ='Residual-RosteredMATRIX-CARER'!D6 -> Carer | C36: ='Residual-RosteredMATRIX-CARER'!C6 -> Armstrong, Gillian | D36: ='Residual-RosteredMATRIX-CARER'!E6 -> 15 | E36: =Max_HRS-Table314[[#This Row],[ROSTERED TIME]] -> 61 | F36: =SUM(H36:AV36) -> 0 | G36: =Table314[[#This Row],[ROSTERED TIME]]+Table314[[#This Row],[CHANGE TIME]] -> 15 | H36: =IF('Residual-RosteredMATRIX-CARER'!F6=0,"",'Residual-RosteredMATRIX-CARER'!F6) | I36: =IF('Residual-RosteredMATRIX-CARER'!G6=0,"",'Residual-RosteredMATRIX-CARER'!G6) | J36: =IF('Residual-RosteredMATRIX-CARER'!H6=0,"",'Residual-RosteredMATRIX-CARER'!H6) | K36: =IF('Residual-RosteredMATRIX-CARER'!I6=0,"",'Residual-RosteredMATRIX-CARER'!I6) | L36: =IF('Residual-RosteredMATRIX-CARER'!J6=0,"",'Residual-RosteredMATRIX-CARER'!J6) | M36: =IF('Residual-RosteredMATRIX-CARER'!K6=0,"",'Residual-RosteredMATRIX-CARER'!K6) | N36: =IF('Residual-RosteredMATRIX-CARER'!L6=0,"",'Residual-RosteredMATRIX-CARER'!L6) -> 0.5/ 7.5 | O36: =IF('Residual-RosteredMATRIX-CARER'!M6=0,"",'Residual-RosteredMATRIX-CARER'!M6) | ... AF36: =IF('Residual-RosteredMATRIX-CARER'!AD6=0,"",'Residual-RosteredMATRIX-CARER'!AD6) -> 0.5/ 7.5 | AG36: =IF('Residual-RosteredMATRIX-CARER'!AE5=0,"",'Residual-RosteredMATRIX-CARER'!AE5) | AH36: =IF('Residual-RosteredMATRIX-CARER'!AF6=0,"",'Residual-RosteredMATRIX-CARER'!AF6) | AI36: =IF('Residual-RosteredMATRIX-CARER'!AG6=0,"",'Residual-RosteredMATRIX-CARER'!AG6) | AJ36: =IF('Residual-RosteredMATRIX-CARER'!AH6=0,"",'Residual-RosteredMATRIX-CARER'!AH6) | AK36: =IF('Residual-RosteredMATRIX-CARER'!AI6=0,"",'Residual-RosteredMATRIX-CARER'!AI6) | AL36: =IF('Residual-RosteredMATRIX-CARER'!AJ6=0,"",'Residual-RosteredMATRIX-CARER'!AJ6) | AM36: =IF('Residual-RosteredMATRIX-CARER'!AK6=0,"",'Residual-RosteredMATRIX-CARER'!AK6) | AN36: =IF('Residual-RosteredMATRIX-CARER'!AL6=0,"",'Residual-RosteredMATRIX-CARER'!AL6) | AO36: =IF('Residual-RosteredMATRIX-CARER'!AM6=0,"",'Residual-RosteredMATRIX-CARER'!AM6) | ... AW36: =IF('Residual-RosteredMATRIX-CARER'!AU6=0,"",'Residual-RosteredMATRIX-CARER'!AU6)
A37: ='Residual-Rostered'!#REF! -> #REF! | B37: ='Residual-RosteredMATRIX-CARER'!D8 -> Carer | C37: ='Residual-RosteredMATRIX-CARER'!C8 -> Aspinall, Samantha | D37: ='Residual-RosteredMATRIX-CARER'!E8 -> 57 | E37: =Max_HRS-Table314[[#This Row],[ROSTERED TIME]] -> 19 | F37: =SUM(H37:AV37) -> 8.3 | G37: =Table314[[#This Row],[ROSTERED TIME]]+Table314[[#This Row],[CHANGE TIME]] -> 65.3 | H37: =IF('Residual-RosteredMATRIX-CARER'!F8=0,"",'Residual-RosteredMATRIX-CARER'!F8) -> 0.5/ 7.5 | I37: =IF('Residual-RosteredMATRIX-CARER'!G8=0,"",'Residual-RosteredMATRIX-CARER'!G8) | J37: =IF('Residual-RosteredMATRIX-CARER'!H8=0,"",'Residual-RosteredMATRIX-CARER'!H8) | K37: =IF('Residual-RosteredMATRIX-CARER'!I8=0,"",'Residual-RosteredMATRIX-CARER'!I8) -> 1.9/ 6 | L37: =IF('Residual-RosteredMATRIX-CARER'!J8=0,"",'Residual-RosteredMATRIX-CARER'!J8) | M37: =IF('Residual-RosteredMATRIX-CARER'!K8=0,"",'Residual-RosteredMATRIX-CARER'!K8) | N37: =IF('Residual-RosteredMATRIX-CARER'!L8=0,"",'Residual-RosteredMATRIX-CARER'!L8) -> 1.9/ 6 | O37: =IF('Residual-RosteredMATRIX-CARER'!M8=0,"",'Residual-RosteredMATRIX-CARER'!M8) | ... S37: =IF('Residual-RosteredMATRIX-CARER'!Q8=0,"",'Residual-RosteredMATRIX-CARER'!Q8) | T37: 7.8 | U37: 0.5 | V37: =IF('Residual-RosteredMATRIX-CARER'!T8=0,"",'Residual-RosteredMATRIX-CARER'!T8) | W37: =IF('Residual-RosteredMATRIX-CARER'!U8=0,"",'Residual-RosteredMATRIX-CARER'!U8) | X37: =IF('Residual-RosteredMATRIX-CARER'!V8=0,"",'Residual-RosteredMATRIX-CARER'!V8) | Y37: =IF('Residual-RosteredMATRIX-CARER'!W8=0,"",'Residual-RosteredMATRIX-CARER'!W8) | Z37: =IF('Residual-RosteredMATRIX-CARER'!X8=0,"",'Residual-RosteredMATRIX-CARER'!X8) | AA37: =IF('Residual-RosteredMATRIX-CARER'!Y8=0,"",'Residual-RosteredMATRIX-CARER'!Y8) | AB37: =IF('Residual-RosteredMATRIX-CARER'!Z8=0,"",'Residual-RosteredMATRIX-CARER'!Z8) | AC37: =IF('Residual-RosteredMATRIX-CARER'!AA8=0,"",'Residual-RosteredMATRIX-CARER'!AA8) -> 0.5/ 7.5 | ... AF37: =IF('Residual-RosteredMATRIX-CARER'!AD8=0,"",'Residual-RosteredMATRIX-CARER'!AD8) -> 0.5/ 7.5 | AG37: =IF('Residual-RosteredMATRIX-CARER'!AE6=0,"",'Residual-RosteredMATRIX-CARER'!AE6) | AH37: =IF('Residual-RosteredMATRIX-CARER'!AF8=0,"",'Residual-RosteredMATRIX-CARER'!AF8) | AI37: =IF('Residual-RosteredMATRIX-CARER'!AG8=0,"",'Residual-RosteredMATRIX-CARER'!AG8) -> 0.5/ 7.5 | AJ37: =IF('Residual-RosteredMATRIX-CARER'!AH8=0,"",'Residual-RosteredMATRIX-CARER'!AH8) | AK37: =IF('Residual-RosteredMATRIX-CARER'!AI8=0,"",'Residual-RosteredMATRIX-CARER'!AI8) | AL37: =IF('Residual-RosteredMATRIX-CARER'!AJ8=0,"",'Residual-RosteredMATRIX-CARER'!AJ8) -> 0.5/ 7.5 | AM37: =IF('Residual-RosteredMATRIX-CARER'!AK8=0,"",'Residual-RosteredMATRIX-CARER'!AK8) | AN37: =IF('Residual-RosteredMATRIX-CARER'!AL8=0,"",'Residual-RosteredMATRIX-CARER'!AL8) | AO37: =IF('Residual-RosteredMATRIX-CARER'!AM8=0,"",'Residual-RosteredMATRIX-CARER'!AM8) | ... AW37: =IF('Residual-RosteredMATRIX-CARER'!AU8=0,"",'Residual-RosteredMATRIX-CARER'!AU8)
A38: ='Residual-Rostered'!#REF! -> #REF! | B38: ='Residual-RosteredMATRIX-CARER'!D67 -> 0 | C38: Christine Clark | D38: ='Residual-RosteredMATRIX-RN'!E67 -> 0 | E38: =Max_HRS-Table314[[#This Row],[ROSTERED TIME]] -> 76 | F38: =SUM(H38:AV38) -> 76.9 | G38: =Table314[[#This Row],[ROSTERED TIME]]+Table314[[#This Row],[CHANGE TIME]] -> 76.9 | H38: =IF('Residual-RosteredMATRIX-RN'!F67=0,"",'Residual-RosteredMATRIX-RN'!F67) | I38: =IF('Residual-RosteredMATRIX-RN'!G67=0,"",'Residual-RosteredMATRIX-RN'!G67) | J38: =IF('Residual-RosteredMATRIX-RN'!H67=0,"",'Residual-RosteredMATRIX-RN'!H67) | K38: =IF('Residual-RosteredMATRIX-RN'!I67=0,"",'Residual-RosteredMATRIX-RN'!I67) | L38: =IF('Residual-RosteredMATRIX-RN'!J67=0,"",'Residual-RosteredMATRIX-RN'!J67) | M38: =IF('Residual-RosteredMATRIX-RN'!K67=0,"",'Residual-RosteredMATRIX-RN'!K67) | N38: 7.8 | O38: =IF('Residual-RosteredMATRIX-RN'!M67=0,"",'Residual-RosteredMATRIX-RN'!M67) | P38: =IF('Residual-RosteredMATRIX-RN'!N67=0,"",'Residual-RosteredMATRIX-RN'!N67) | Q38: 7.8 | S38: =IF('Residual-RosteredMATRIX-RN'!Q67=0,"",'Residual-RosteredMATRIX-RN'!Q67) | T38: 7.8 | U38: 0.5 | V38: =IF('Residual-RosteredMATRIX-RN'!T67=0,"",'Residual-RosteredMATRIX-RN'!T67) | W38: 7.2 | X38: =IF('Residual-RosteredMATRIX-RN'!V67=0,"",'Residual-RosteredMATRIX-RN'!V67) | Y38: =IF('Residual-RosteredMATRIX-RN'!W67=0,"",'Residual-RosteredMATRIX-RN'!W67) | Z38: 7.2 | AB38: =IF('Residual-RosteredMATRIX-RN'!Z67=0,"",'Residual-RosteredMATRIX-RN'!Z67) | AE38: =IF('Residual-RosteredMATRIX-RN'!AC67=0,"",'Residual-RosteredMATRIX-RN'!AC67) | AF38: =IF('Residual-RosteredMATRIX-RN'!AD67=0,"",'Residual-RosteredMATRIX-RN'!AD67) | AG38: =IF('Residual-RosteredMATRIX-CARER'!AE7=0,"",'Residual-RosteredMATRIX-CARER'!AE7) | AH38: =IF('Residual-RosteredMATRIX-RN'!AF67=0,"",'Residual-RosteredMATRIX-RN'!AF67) | AI38: 7.8 | AK38: =IF('Residual-RosteredMATRIX-RN'!AI67=0,"",'Residual-RosteredMATRIX-RN'!AI67) | AL38: =IF('Residual-RosteredMATRIX-RN'!AJ67=0,"",'Residual-RosteredMATRIX-RN'!AJ67) | AM38: 7.8 | AN38: =IF('Residual-RosteredMATRIX-RN'!AL67=0,"",'Residual-RosteredMATRIX-RN'!AL67) | AO38: 7.8 | AP38: =IF('Residual-RosteredMATRIX-RN'!AN67=0,"",'Residual-RosteredMATRIX-RN'!AN67) | AQ38: =IF('Residual-RosteredMATRIX-RN'!AO67=0,"",'Residual-RosteredMATRIX-RN'!AO67) | AR38: 7.8 | AS38: =IF('Residual-RosteredMATRIX-RN'!AQ67=0,"",'Residual-RosteredMATRIX-RN'!AQ67) | AT38: =IF('Residual-RosteredMATRIX-RN'!AR67=0,"",'Residual-RosteredMATRIX-RN'!AR67) | AU38: 7.4 | AV38: =IF('Residual-RosteredMATRIX-RN'!AT67=0,"",'Residual-RosteredMATRIX-RN'!AT67) | AW38: =IF('Residual-RosteredMATRIX-RN'!AU67=0,"",'Residual-RosteredMATRIX-RN'!AU67)
A39: ='Residual-Rostered'!#REF! -> #REF! | B39: ='Residual-RosteredMATRIX-CARER'!D10 -> Carer | C39: ='Residual-RosteredMATRIX-CARER'!C10 -> Brown, Maria | D39: ='Residual-RosteredMATRIX-CARER'!E10 -> 60 | E39: =Max_HRS-Table314[[#This Row],[ROSTERED TIME]] -> 16 | F39: =SUM(H39:AV39) -> 0 | G39: =Table314[[#This Row],[ROSTERED TIME]]+Table314[[#This Row],[CHANGE TIME]] -> 60 | H39: =IF('Residual-RosteredMATRIX-CARER'!F10=0,"",'Residual-RosteredMATRIX-CARER'!F10) -> 0.5/ 7.5 | I39: =IF('Residual-RosteredMATRIX-CARER'!G10=0,"",'Residual-RosteredMATRIX-CARER'!G10) | J39: =IF('Residual-RosteredMATRIX-CARER'!H10=0,"",'Residual-RosteredMATRIX-CARER'!H10) | K39: =IF('Residual-RosteredMATRIX-CARER'!I10=0,"",'Residual-RosteredMATRIX-CARER'!I10) | L39: =IF('Residual-RosteredMATRIX-CARER'!J10=0,"",'Residual-RosteredMATRIX-CARER'!J10) | M39: =IF('Residual-RosteredMATRIX-CARER'!K10=0,"",'Residual-RosteredMATRIX-CARER'!K10) | N39: =IF('Residual-RosteredMATRIX-CARER'!L10=0,"",'Residual-RosteredMATRIX-CARER'!L10) | O39: =IF('Residual-RosteredMATRIX-CARER'!M10=0,"",'Residual-RosteredMATRIX-CARER'!M10) | ... AF39: =IF('Residual-RosteredMATRIX-CARER'!AD10=0,"",'Residual-RosteredMATRIX-CARER'!AD10) | AG39: =IF('Residual-RosteredMATRIX-CARER'!AE8=0,"",'Residual-RosteredMATRIX-CARER'!AE8) | AH39: =IF('Residual-RosteredMATRIX-CARER'!AF10=0,"",'Residual-RosteredMATRIX-CARER'!AF10) | AI39: =IF('Residual-RosteredMATRIX-CARER'!AG10=0,"",'Residual-RosteredMATRIX-CARER'!AG10) -> 0.5/ 7.5 | AJ39: =IF('Residual-RosteredMATRIX-CARER'!AH10=0,"",'Residual-RosteredMATRIX-CARER'!AH10) | AK39: =IF('Residual-RosteredMATRIX-CARER'!AI10=0,"",'Residual-RosteredMATRIX-CARER'!AI10) | AL39: =IF('Residual-RosteredMATRIX-CARER'!AJ10=0,"",'Residual-RosteredMATRIX-CARER'!AJ10) -> 0.5/ 7.5 | AM39: =IF('Residual-RosteredMATRIX-CARER'!AK10=0,"",'Residual-RosteredMATRIX-CARER'!AK10) | AN39: =IF('Residual-RosteredMATRIX-CARER'!AL10=0,"",'Residual-RosteredMATRIX-CARER'!AL10) | AO39: =IF('Residual-RosteredMATRIX-CARER'!AM10=0,"",'Residual-RosteredMATRIX-CARER'!AM10) -> 0.5/ 7.5 | ... AW39: =IF('Residual-RosteredMATRIX-CARER'!AU10=0,"",'Residual-RosteredMATRIX-CARER'!AU10)
A40: ='Residual-Rostered'!#REF! -> #REF! | B40: ='Residual-RosteredMATRIX-CARER'!D12 -> Carer | C40: ='Residual-RosteredMATRIX-CARER'!C12 -> Burgmann, Robyn | D40: ='Residual-RosteredMATRIX-CARER'!E12 -> 64 | E40: =Max_HRS-Table314[[#This Row],[ROSTERED TIME]] -> 12 | F40: =SUM(H40:AV40) -> 7.8 | G40: =Table314[[#This Row],[ROSTERED TIME]]+Table314[[#This Row],[CHANGE TIME]] -> 71.8 | H40: =IF('Residual-RosteredMATRIX-CARER'!F12=0,"",'Residual-RosteredMATRIX-CARER'!F12) | I40: =IF('Residual-RosteredMATRIX-CARER'!G12=0,"",'Residual-RosteredMATRIX-CARER'!G12) -> 0/ 7.8 | J40: =IF('Residual-RosteredMATRIX-CARER'!H12=0,"",'Residual-RosteredMATRIX-CARER'!H12) -> 0/ 0.2 | K40: =IF('Residual-RosteredMATRIX-CARER'!I12=0,"",'Residual-RosteredMATRIX-CARER'!I12) | L40: =IF('Residual-RosteredMATRIX-CARER'!J12=0,"",'Residual-RosteredMATRIX-CARER'!J12) -> 0/ 7.8 | M40: =IF('Residual-RosteredMATRIX-CARER'!K12=0,"",'Residual-RosteredMATRIX-CARER'!K12) -> 0/ 0.2 | N40: =IF('Residual-RosteredMATRIX-CARER'!L12=0,"",'Residual-RosteredMATRIX-CARER'!L12) | O40: =IF('Residual-RosteredMATRIX-CARER'!M12=0,"",'Residual-RosteredMATRIX-CARER'!M12) | P40: 7.8 | Q40: =IF('Residual-RosteredMATRIX-CARER'!O12=0,"",'Residual-RosteredMATRIX-CARER'!O12) | R40: =IF('Residual-RosteredMATRIX-CARER'!P12=0,"",'Residual-RosteredMATRIX-CARER'!P12) | T40: =IF('Residual-RosteredMATRIX-CARER'!R12=0,"",'Residual-RosteredMATRIX-CARER'!R12) | U40: =IF('Residual-RosteredMATRIX-CARER'!S12=0,"",'Residual-RosteredMATRIX-CARER'!S12) | V40: =IF('Residual-RosteredMATRIX-CARER'!T12=0,"",'Residual-RosteredMATRIX-CARER'!T12) | W40: =IF('Residual-RosteredMATRIX-CARER'!U12=0,"",'Residual-RosteredMATRIX-CARER'!U12) | X40: =IF('Residual-RosteredMATRIX-CARER'!V12=0,"",'Residual-RosteredMATRIX-CARER'!V12) | Y40: =IF('Residual-RosteredMATRIX-CARER'!W12=0,"",'Residual-RosteredMATRIX-CARER'!W12) | Z40: =IF('Residual-RosteredMATRIX-CARER'!X12=0,"",'Residual-RosteredMATRIX-CARER'!X12) | AA40: =IF('Residual-RosteredMATRIX-CARER'!Y12=0,"",'Residual-RosteredMATRIX-CARER'!Y12) | ... AF40: =IF('Residual-RosteredMATRIX-CARER'!AD12=0,"",'Residual-RosteredMATRIX-CARER'!AD12) | AG40: =IF('Residual-RosteredMATRIX-CARER'!AE9=0,"",'Residual-RosteredMATRIX-CARER'!AE9) -> 0/ 0.5 | AH40: =IF('Residual-RosteredMATRIX-CARER'!AF12=0,"",'Residual-RosteredMATRIX-CARER'!AF12) -> 0/ 0.2 | AI40: =IF('Residual-RosteredMATRIX-CARER'!AG12=0,"",'Residual-RosteredMATRIX-CARER'!AG12) | AJ40: =IF('Residual-RosteredMATRIX-CARER'!AH12=0,"",'Residual-RosteredMATRIX-CARER'!AH12) -> 0/ 7.8 | AK40: =IF('Residual-RosteredMATRIX-CARER'!AI12=0,"",'Residual-RosteredMATRIX-CARER'!AI12) -> 0/ 0.2 | AL40: =IF('Residual-RosteredMATRIX-CARER'!AJ12=0,"",'Residual-RosteredMATRIX-CARER'!AJ12) | AM40: =IF('Residual-RosteredMATRIX-CARER'!AK12=0,"",'Residual-RosteredMATRIX-CARER'!AK12) | AN40: =IF('Residual-RosteredMATRIX-CARER'!AL12=0,"",'Residual-RosteredMATRIX-CARER'!AL12) | AO40: =IF('Residual-RosteredMATRIX-CARER'!AM12=0,"",'Residual-RosteredMATRIX-CARER'!AM12) | ... AW40: =IF('Residual-RosteredMATRIX-CARER'!AU12=0,"",'Residual-RosteredMATRIX-CARER'!AU12) -> 0/ 0.2
A41: ='Residual-Rostered'!#REF! -> #REF! | B41: ='Residual-RosteredMATRIX-CARER'!D13 -> Carer | C41: ='Residual-RosteredMATRIX-CARER'!C13 -> Campbell, Marley | D41: ='Residual-RosteredMATRIX-CARER'!E13 -> 68 | E41: =Max_HRS-Table314[[#This Row],[ROSTERED TIME]] -> 8 | F41: =SUM(H41:AV41) -> 1 | G41: =Table314[[#This Row],[ROSTERED TIME]]+Table314[[#This Row],[CHANGE TIME]] -> 69 | H41: =IF('Residual-RosteredMATRIX-CARER'!F13=0,"",'Residual-RosteredMATRIX-CARER'!F13) | I41: =IF('Residual-RosteredMATRIX-CARER'!G13=0,"",'Residual-RosteredMATRIX-CARER'!G13) -> 0/ 7.8 | J41: =IF('Residual-RosteredMATRIX-CARER'!H13=0,"",'Residual-RosteredMATRIX-CARER'!H13) -> 0/ 0.2 | K41: =IF('Residual-RosteredMATRIX-CARER'!I13=0,"",'Residual-RosteredMATRIX-CARER'!I13) | L41: =IF('Residual-RosteredMATRIX-CARER'!J13=0,"",'Residual-RosteredMATRIX-CARER'!J13) -> 0/ 7.8 | M41: =IF('Residual-RosteredMATRIX-CARER'!K13=0,"",'Residual-RosteredMATRIX-CARER'!K13) -> 0/ 0.2 | N41: =IF('Residual-RosteredMATRIX-CARER'!L13=0,"",'Residual-RosteredMATRIX-CARER'!L13) | O41: =IF('Residual-RosteredMATRIX-CARER'!M13=0,"",'Residual-RosteredMATRIX-CARER'!M13) | ... AF41: =IF('Residual-RosteredMATRIX-CARER'!AD13=0,"",'Residual-RosteredMATRIX-CARER'!AD13) | AG41: =IF('Residual-RosteredMATRIX-CARER'!AE10=0,"",'Residual-RosteredMATRIX-CARER'!AE10) | AH41: =IF('Residual-RosteredMATRIX-CARER'!AF13=0,"",'Residual-RosteredMATRIX-CARER'!AF13) | AI41: =IF('Residual-RosteredMATRIX-CARER'!AG13=0,"",'Residual-RosteredMATRIX-CARER'!AG13) | AJ41: =IF('Residual-RosteredMATRIX-CARER'!AH13=0,"",'Residual-RosteredMATRIX-CARER'!AH13) -> 1/ 7 | AK41: =IF('Residual-RosteredMATRIX-CARER'!AI13=0,"",'Residual-RosteredMATRIX-CARER'!AI13) | AL41: =IF('Residual-RosteredMATRIX-CARER'!AJ13=0,"",'Residual-RosteredMATRIX-CARER'!AJ13) | AM41: 1 | AN41: =IF('Residual-RosteredMATRIX-CARER'!AL13=0,"",'Residual-RosteredMATRIX-CARER'!AL13) | AO41: =IF('Residual-RosteredMATRIX-CARER'!AM13=0,"",'Residual-RosteredMATRIX-CARER'!AM13) | AP41: =IF('Residual-RosteredMATRIX-CARER'!AN13=0,"",'Residual-RosteredMATRIX-CARER'!AN13) -> 1/ 7 | AQ41: =IF('Residual-RosteredMATRIX-CARER'!AO13=0,"",'Residual-RosteredMATRIX-CARER'!AO13) | AR41: =IF('Residual-RosteredMATRIX-CARER'!AP13=0,"",'Residual-RosteredMATRIX-CARER'!AP13) | AS41: =IF('Residual-RosteredMATRIX-CARER'!AQ13=0,"",'Residual-RosteredMATRIX-CARER'!AQ13) | AT41: =IF('Residual-RosteredMATRIX-CARER'!AR13=0,"",'Residual-RosteredMATRIX-CARER'!AR13) | AU41: =IF('Residual-RosteredMATRIX-CARER'!AS13=0,"",'Residual-RosteredMATRIX-CARER'!AS13) | ... AW41: =IF('Residual-RosteredMATRIX-CARER'!AU13=0,"",'Residual-RosteredMATRIX-CARER'!AU13)
