Workbook

Sheet Primary Inputs
A1: Primary Input data sheet
A3: Use this sheet to record the primary data and information used in this model. This includes all names referred to in subsequent worksheets
A5: Client name: | B5: Christadelphian Aged Care
A7: Residential Aged Care Data Sheet
A8: Roster Code (in this model) | B8: Site(s) | C8: Wing/Ward | D8: Wing Type | E8: Maximum number of beds/licences | F8: Location | G8: Modified Monash Model (MMM) location Rating | H8: Target Occupany (Number) | I8: Target Occupany (%) | J8: Wage Data
A9: G1 | B9: Ashburn House | C9: Used for RNs only | D9: N/A | E9: 99 | F9: 15 Gloucester Ave, North Parramatta, NSW, 2151 | G9: 1 | H9: ='AN-ACC Simple'!B7 -> 99 | I9: =H9/E9 -> 1 | J9: BCAC EA
A10: G2 | B10: Ashburn House | C10: Used for Carers Only | D10: N/A | E10: 0 | F10: 15 Gloucester Ave, North Parramatta, NSW, 2151 | G10: 1 | H10: ='AN-ACC Simple'!B8 -> 0 | I10: =H10/E10 -> #DIV/0! | J10: BCAC EA
A11: G3 | B11: Ashburn House | C11: Hidden | D11: N/A | E11: 0 | F11: 15 Gloucester Ave, North Parramatta, NSW, 2151 | G11: 1 | H11: ='AN-ACC Simple'!B9 -> 0 | I11: =H11/E11 -> #DIV/0! | J11: BCAC EA
A12: G4 | B12: Ashburn House | C12: Hidden | D12: Roster Only | E12: 0 | F12: 15 Gloucester Ave, North Parramatta, NSW, 2151 | J12: BCAC EA
A13: G5 | B13: Ashburn House | C13: MANAGEMENT | D13: Roster Only | E13: 0 | F13: 15 Gloucester Ave, North Parramatta, NSW, 2151 | J13: BCAC EA

Sheet AN-ACC Minutes
A1: ='Primary Inputs'!$B$5 -> Christadelphian Aged Care
A3: AN-ACC Minutes Comparison
A5: In this sheet, we compare the floor hours targets in the AN-ACC Funding mechanism against the master roster for each facility.
A6: Care minutes have been converted into hours to match the roster data
A8: ='Primary Inputs'!B9 -> Ashburn House
A10: AT CURRENT OCCUPANCY | C10: TOTAL CARE HOURS (Including RN and Carer Allocation) | K10: RN HOURS ONLY (Excluding carer hours) | S10: CARER HOURS ONLY (Excluding RN hours)
A13: Ward | B13: Resident Count | C13: Weekly AN-ACC Target (Hrs) | E13: Weekly Roster | F13: Allocation to AN-ACC | G13: AN-ACC Hours | I13: Surplus/ Shortfall in Hours | K13: Weekly RN AN-ACC Target (Hrs) | M13: Roster Minutes | N13: Allocation to AN-ACC | O13: AN-ACC Hours | Q13: Surplus/ Shortfall in Hours | S13: Weekly RN AN-ACC Target (Hrs) | U13: Roster Minutes | V13: Allocation to AN-ACC | W13: AN-ACC Hours | Y13: Surplus/ Shortfall in Hours
A14: CARE ROSTERS
A15: Combined Wards | B15: ='AN-ACC Simple'!B7 -> 99 | C15: ='AN-ACC Simple'!E7*7 -> 2511.201 | E15: ='Summary Roster'!T13 -> 2671 | F15: =IFERROR(G15/E15,0) -> 90.268813 | G15: 241108 | I15: =G15-C15 -> 238596.8 | K15: ='AN-ACC Simple'!I7*7 -> 512.82 | M15: ='Summary Roster'!T14 -> 494 | N15: =IFERROR(O15/M15,0) -> 1 | O15: ='Summary Roster'!W14 -> 494 | Q15: =O15-K15 -> -18.82 | S15: =C15-K15 -> 1998.381 | U15: =E15-M15 -> 2177 | V15: =IFERROR(W15/U15,0) -> 110.52549 | W15: =G15-O15 -> 240614 | Y15: =W15-S15 -> 238615.62
A17: Total | B17: =SUM(B15:B16) -> 99 | C17: =SUBTOTAL(9,C15:C16) -> 2511.201 | E17: =SUBTOTAL(9,E15:E16) -> 2671 | G17: =SUBTOTAL(9,G15:G16) -> 241108 | I17: =SUBTOTAL(9,I15:I16) -> 238596.8 | K17: =SUBTOTAL(9,K15:K16) -> 512.82 | M17: =SUBTOTAL(9,M15:M16) -> 494 | O17: =SUBTOTAL(9,O15:O16) -> 494 | Q17: =SUBTOTAL(9,Q15:Q16) -> -18.82 | S17: =SUBTOTAL(9,S15:S16) -> 1998.381 | U17: =SUBTOTAL(9,U15:U16) -> 2177 | W17: =SUBTOTAL(9,W15:W16) -> 240614 | Y17: =SUBTOTAL(9,Y15:Y16) -> 238615.62
A19: Office/Shared Hours
A20: LIFESTYLE | E20: ='Summary Roster'!T17 -> 0 | F20: =IFERROR(G20/E20,0) -> 0 | G20: ='Summary Roster'!W17 -> 0 | I20: =G20-C20 -> 0 | U20: =E20-M20 -> 0 | W20: =G20-O20 -> 0 | Y20: =W20-S20 -> 0
A21: KITCHEN | E21: ='Summary Roster'!T20 -> 0 | F21: =IFERROR(G21/E21,0) -> 0 | G21: ='Summary Roster'!W20 -> 0 | I21: =G21-C21 -> 0 | U21: =E21-M21 -> 0 | W21: =G21-O21 -> 0 | Y21: =W21-S21 -> 0
A22: LAUNDRY | E22: ='Summary Roster'!T21 -> 0 | F22: =IFERROR(G22/E22,0) -> 0 | G22: ='Summary Roster'!W21 -> 0 | I22: =G22-C22 -> 0 | U22: =E22-M22 -> 0 | W22: =G22-O22 -> 0 | Y22: =W22-S22 -> 0
A23: DRIVER | E23: ='Summary Roster'!T22 -> 0 | F23: =IFERROR(G23/E23,0) -> 0 | G23: ='Summary Roster'!W22 -> 0 | I23: =G23-C23 -> 0 | U23: =E23-M23 -> 0 | W23: =G23-O23 -> 0 | Y23: =W23-S23 -> 0
A24: CLINICAL MANAGEMENT | E24: ='Summary Roster'!T25 -> 80 | F24: =IFERROR(G24/E24,0) -> 0.6 | G24: ='Summary Roster'!W24 -> 48 | I24: =G24-C24 -> 48 | M24: ='Summary Roster'!T25 -> 80 | N24: =IFERROR(O24/M24,0) -> 0.6 | O24: ='Summary Roster'!W25 -> 48 | Q24: =O24-K24 -> 48 | U24: =E24-M24 -> 0 | V24: =IFERROR(W24/U24,0) -> 0 | W24: =G24-O24 -> 0 | Y24: =W24-S24 -> 0
A25: NON-CLINICAL MANAGEMENT | E25: ='Summary Roster'!T26 -> 0 | F25: =IFERROR(G25/E25,0) -> 0 | G25: ='Summary Roster'!W26 -> 0 | I25: =G25-C25 -> 0 | U25: =E25-M25 -> 0 | W25: =G25-O25 -> 0 | Y25: =W25-S25 -> 0
A27: Total Office/Shared Hours | E27: =SUBTOTAL(9,E19:E26) -> 80 | G27: =SUBTOTAL(9,G19:G26) -> 48 | I27: =SUBTOTAL(9,I19:I26) -> 48 | M27: =SUBTOTAL(9,M19:M26) -> 80 | O27: =SUBTOTAL(9,O19:O26) -> 48 | Q27: =SUBTOTAL(9,Q19:Q26) -> 48 | U27: =SUBTOTAL(9,U19:U26) -> 0 | W27: =SUBTOTAL(9,W19:W26) -> 0 | Y27: =SUBTOTAL(9,Y19:Y26) -> 0
A29: TOTAL (In Hours) | E29: =SUBTOTAL(9,E15:E28) -> 2751 | G29: =SUBTOTAL(9,G15:G28) -> 241156 | I29: =SUBTOTAL(9,I15:I28) -> 238644.8 | M29: =SUBTOTAL(9,M15:M28) -> 574 | O29: =SUBTOTAL(9,O15:O28) -> 542 | Q29: =SUBTOTAL(9,Q15:Q28) -> 29.18 | U29: =SUBTOTAL(9,U15:U28) -> 2177 | W29: =SUBTOTAL(9,W15:W28) -> 240614 | Y29: =SUBTOTAL(9,Y15:Y28) -> 238615.62
A30: Equivalent Surplus / Deficit Shifts (each at 8 hours) | I30: =I29/8 -> 29830.6 | Q30: =Q29/8 -> 3.6475 | Y30: =Y29/8 -> 29826.952

Sheet AN-ACC Simple
A1: Client Name: | C1: ='Primary Inputs'!$B$5 -> Christadelphian Aged Care
A3: AN-ACC Worksheet
P4: Data from AN-ACC Worksheet
A6: Ward | B6: Type in Number | C6: Published Minutes Target | D6: Target Minutes per Day | E6: Target Hours per Day | G6: Published RN Minutes Target | H6: Target RN Minutes per Day | I6: Target RN Hours per Day | M6: Predicted Number of Empty Beds | P6: Calculated Minutes
A7: ='Primary Inputs'!C9 -> Used for RNs only | B7: 99 | C7: 217.42 | D7: =B7*C7 -> 21524.58 | E7: =D7/60 -> 358.743 | F7: =E7*7 -> 2511.201 | G7: 44.4 | H7: =B7*G7 -> 4395.6 | I7: =H7/60 -> 73.26 | J7: =I7*7 -> 512.82 | M7: 0 | P7: ='AN-ACC Worksheet'!H30 -> 207.56566
A8: ='Primary Inputs'!C10 -> Used for Carers Only | B8: ='Primary Inputs'!E10-M8 -> 0 | C8: =$C$7 -> 217.42 | D8: =B8*C8 -> 0 | E8: =D8/60 -> 0 | G8: =$G$7 -> 44.4 | H8: =B8*G8 -> 0 | I8: =H8/60 -> 0 | M8: 0 | P8: ='AN-ACC Worksheet'!H56 -> #DIV/0!
A9: ='Primary Inputs'!C11 -> Hidden | B9: ='Primary Inputs'!E11-M9 -> 0 | C9: =$C$7 -> 217.42 | D9: =B9*C9 -> 0 | E9: =D9/60 -> 0 | G9: =$G$7 -> 44.4 | H9: =B9*G9 -> 0 | I9: =H9/60 -> 0 | M9: 0 | P9: ='AN-ACC Worksheet'!H82 -> #DIV/0!
A13: Total | B13: =SUM(B7:B12) -> 99 | D13: =SUM(D7:D12) -> 21524.58 | E13: =SUM(E7:E12) -> 358.743 | H13: =SUM(H7:H12) -> 4395.6 | I13: =SUM(I7:I12) -> 73.26 | P13: =AVERAGE(P7:P9) -> #DIV/0!
A14: Average | D14: =D13/$B13 -> 217.42 | H14: =H13/$B13 -> 44.4
C18: Previous | G18: Previous
C19: 205.14 | G19: 40.71
B20: Change | C20: =C7/C19 -> 1.0598616 | F20: Change | G20: =G7/G19 -> 1.0906411

Sheet Summary Roster
A1: ='Primary Inputs'!$B$5 -> Christadelphian Aged Care
A3: Current Roster Budget
A5: Roster Code (in this model) | B5: Site(s) | C5: Wing | D5: Wing Type | E5: Maximum number of beds/licences
A6: ='Primary Inputs'!A9 -> G1 | B6: =VLOOKUP($A6,'Primary Inputs'!$A$9:$J$13,2,FALSE) -> Ashburn House | C6: =VLOOKUP($A6,'Primary Inputs'!$A$9:$J$13,3,FALSE) -> Used for RNs only | D6: =VLOOKUP($A6,'Primary Inputs'!$A$9:$J$13,4,FALSE) -> N/A | E6: =VLOOKUP($A6,'Primary Inputs'!$A$9:$J$13,5,FALSE) -> 99
L9: Roster Hours per Day | T9: Total Weekly Hours | AH9: Loading per day (Higher of shift loading or penalty rate. 100% is Base Pay) | AP9: Hourly Rate By Shift and Day
A10: Location | B10: Shift | C10: Role | D10: Headcount per shift | E10: Notes | F10: Shift Start | G10: Shift End | H10: Shift Hours (Excl Break) | I10: Break | J10: Shift less breaks | K10: Total Hours | L10: Mon | M10: Tue | N10: Wed | O10: Thu | P10: Fri | Q10: Sat | R10: Sun | V10: AN-ACC Allocation (%) | W10: An-ACC Hours | Y10: Super Loading | Z10: Annual Leave Loading | AA10: Sick Leave Loading | AB10: Long Service Leave Loading | AC10: Workers Comp | AD10: Total Loading | AF10: Base Rate | AG10: Shift Loading | AH10: Mon | AI10: Tue | AJ10: Wed | AK10: Thu | AL10: Fri | AM10: Sat | AN10: Sun | AP10: Mon | AQ10: Tue | AR10: Wed | AS10: Thu | AT10: Fri | AU10: Sat | AV10: Sun
A12: ="TOTAL "&$C$6&" ROSTER" -> TOTAL Used for RNs only ROSTER | L12: =SUBTOTAL(9,L13:L28) -> 396.5 | M12: =SUBTOTAL(9,M13:M28) -> 404 | N12: =SUBTOTAL(9,N13:N28) -> 396.5 | O12: =SUBTOTAL(9,O13:O28) -> 396.5 | P12: =SUBTOTAL(9,P13:P28) -> 396.5 | Q12: =SUBTOTAL(9,Q13:Q28) -> 380.5 | R12: =SUBTOTAL(9,R13:R28) -> 380.5 | T12: =SUBTOTAL(9,T13:T28) -> 2751 | V12: =IFERROR(W12/T12,0) -> 0.98836787 | W12: =SUBTOTAL(9,W13:W28) -> 2719
A13: CARE ROSTER | L13: =SUBTOTAL(9,L14:L15) -> 380.5 | M13: =SUBTOTAL(9,M14:M15) -> 388 | N13: =SUBTOTAL(9,N14:N15) -> 380.5 | O13: =SUBTOTAL(9,O14:O15) -> 380.5 | P13: =SUBTOTAL(9,P14:P15) -> 380.5 | Q13: =SUBTOTAL(9,Q14:Q15) -> 380.5 | R13: =SUBTOTAL(9,R14:R15) -> 380.5 | T13: =SUBTOTAL(9,T14:T15) -> 2671 | V13: =IFERROR(W13/T13,0) -> 1 | W13: =SUBTOTAL(9,W14:W15) -> 2671
A14: Registered Nurses | C14: RN | L14: ='Roster - G1 - RN'!L14+'Roster - G2 - Carer'!L14+'Roster - G3 - Ward 3'!L14+'Roster - G4 - Services'!L14+'Roster - G5 - Mgmt'!L14 -> 69.5 | M14: ='Roster - G1 - RN'!M14+'Roster - G2 - Carer'!M14+'Roster - G3 - Ward 3'!M14+'Roster - G4 - Services'!M14+'Roster - G5 - Mgmt'!M14 -> 77 | N14: ='Roster - G1 - RN'!N14+'Roster - G2 - Carer'!N14+'Roster - G3 - Ward 3'!N14+'Roster - G4 - Services'!N14+'Roster - G5 - Mgmt'!N14 -> 69.5 | O14: ='Roster - G1 - RN'!O14+'Roster - G2 - Carer'!O14+'Roster - G3 - Ward 3'!O14+'Roster - G4 - Services'!O14+'Roster - G5 - Mgmt'!O14 -> 69.5 | P14: ='Roster - G1 - RN'!P14+'Roster - G2 - Carer'!P14+'Roster - G3 - Ward 3'!P14+'Roster - G4 - Services'!P14+'Roster - G5 - Mgmt'!P14 -> 69.5 | Q14: ='Roster - G1 - RN'!Q14+'Roster - G2 - Carer'!Q14+'Roster - G3 - Ward 3'!Q14+'Roster - G4 - Services'!Q14+'Roster - G5 - Mgmt'!Q14 -> 69.5 | R14: ='Roster - G1 - RN'!R14+'Roster - G2 - Carer'!R14+'Roster - G3 - Ward 3'!R14+'Roster - G4 - Services'!R14+'Roster - G5 - Mgmt'!R14 -> 69.5 | T14: =SUM(L14:R14) -> 494 | V14: =IFERROR(W14/T14,0) -> 1 | W14: ='Roster - G1 - RN'!W14+'Roster - G2 - Carer'!W14+'Roster - G3 - Ward 3'!W14+'Roster - G4 - Services'!W14+'Roster - G5 - Mgmt'!W14 -> 494
A15: Carers and ENs | C15: CARER | L15: ='Roster - G1 - RN'!L15+'Roster - G2 - Carer'!L15+'Roster - G3 - Ward 3'!L15+'Roster - G4 - Services'!L15+'Roster - G5 - Mgmt'!L15 -> 311 | M15: ='Roster - G1 - RN'!M15+'Roster - G2 - Carer'!M15+'Roster - G3 - Ward 3'!M15+'Roster - G4 - Services'!M15+'Roster - G5 - Mgmt'!M15 -> 311 | N15: ='Roster - G1 - RN'!N15+'Roster - G2 - Carer'!N15+'Roster - G3 - Ward 3'!N15+'Roster - G4 - Services'!N15+'Roster - G5 - Mgmt'!N15 -> 311 | O15: ='Roster - G1 - RN'!O15+'Roster - G2 - Carer'!O15+'Roster - G3 - Ward 3'!O15+'Roster - G4 - Services'!O15+'Roster - G5 - Mgmt'!O15 -> 311 | P15: ='Roster - G1 - RN'!P15+'Roster - G2 - Carer'!P15+'Roster - G3 - Ward 3'!P15+'Roster - G4 - Services'!P15+'Roster - G5 - Mgmt'!P15 -> 311 | Q15: ='Roster - G1 - RN'!Q15+'Roster - G2 - Carer'!Q15+'Roster - G3 - Ward 3'!Q15+'Roster - G4 - Services'!Q15+'Roster - G5 - Mgmt'!Q15 -> 311 | R15: ='Roster - G1 - RN'!R15+'Roster - G2 - Carer'!R15+'Roster - G3 - Ward 3'!R15+'Roster - G4 - Services'!R15+'Roster - G5 - Mgmt'!R15 -> 311 | T15: =SUM(L15:R15) -> 2177 | V15: =IFERROR(W15/T15,0) -> 1 | W15: ='Roster - G1 - RN'!W15+'Roster - G2 - Carer'!W15+'Roster - G3 - Ward 3'!W15+'Roster - G4 - Services'!W15+'Roster - G5 - Mgmt'!W15 -> 2177
A17: LIFESTYLE | C17: LIFESTYLE | L17: ='Roster - G1 - RN'!L17+'Roster - G2 - Carer'!L17+'Roster - G3 - Ward 3'!L17+'Roster - G4 - Services'!L17+'Roster - G5 - Mgmt'!L17 -> 0 | M17: ='Roster - G1 - RN'!M17+'Roster - G2 - Carer'!M17+'Roster - G3 - Ward 3'!M17+'Roster - G4 - Services'!M17+'Roster - G5 - Mgmt'!M17 -> 0 | N17: ='Roster - G1 - RN'!N17+'Roster - G2 - Carer'!N17+'Roster - G3 - Ward 3'!N17+'Roster - G4 - Services'!N17+'Roster - G5 - Mgmt'!N17 -> 0 | O17: ='Roster - G1 - RN'!O17+'Roster - G2 - Carer'!O17+'Roster - G3 - Ward 3'!O17+'Roster - G4 - Services'!O17+'Roster - G5 - Mgmt'!O17 -> 0 | P17: ='Roster - G1 - RN'!P17+'Roster - G2 - Carer'!P17+'Roster - G3 - Ward 3'!P17+'Roster - G4 - Services'!P17+'Roster - G5 - Mgmt'!P17 -> 0 | Q17: ='Roster - G1 - RN'!Q17+'Roster - G2 - Carer'!Q17+'Roster - G3 - Ward 3'!Q17+'Roster - G4 - Services'!Q17+'Roster - G5 - Mgmt'!Q17 -> 0 | R17: ='Roster - G1 - RN'!R17+'Roster - G2 - Carer'!R17+'Roster - G3 - Ward 3'!R17+'Roster - G4 - Services'!R17+'Roster - G5 - Mgmt'!R17 -> 0 | T17: =SUM(L17:R17) -> 0 | V17: =IFERROR(W17/T17,0) -> 0 | W17: ='Roster - G1 - RN'!W17+'Roster - G2 - Carer'!W17+'Roster - G3 - Ward 3'!W17+'Roster - G4 - Services'!W17+'Roster - G5 - Mgmt'!W17 -> 0
A19: KITCHEN & LAUNDRY | L19: =SUBTOTAL(9,L20:L23) -> 0 | M19: =SUBTOTAL(9,M20:M23) -> 0 | N19: =SUBTOTAL(9,N20:N23) -> 0 | O19: =SUBTOTAL(9,O20:O23) -> 0 | P19: =SUBTOTAL(9,P20:P23) -> 0 | Q19: =SUBTOTAL(9,Q20:Q23) -> 0 | R19: =SUBTOTAL(9,R20:R23) -> 0 | T19: =SUBTOTAL(9,T20:T23) -> 0 | V19: =IFERROR(W19/T19,0) -> 0 | W19: =SUBTOTAL(9,W20:W23) -> 0
A20: Chef, Kitchen Hand and Servery | C20: KITCHEN | L20: ='Roster - G1 - RN'!L20+'Roster - G2 - Carer'!L20+'Roster - G3 - Ward 3'!L20+'Roster - G4 - Services'!L20+'Roster - G5 - Mgmt'!L20 -> 0 | M20: ='Roster - G1 - RN'!M20+'Roster - G2 - Carer'!M20+'Roster - G3 - Ward 3'!M20+'Roster - G4 - Services'!M20+'Roster - G5 - Mgmt'!M20 -> 0 | N20: ='Roster - G1 - RN'!N20+'Roster - G2 - Carer'!N20+'Roster - G3 - Ward 3'!N20+'Roster - G4 - Services'!N20+'Roster - G5 - Mgmt'!N20 -> 0 | O20: ='Roster - G1 - RN'!O20+'Roster - G2 - Carer'!O20+'Roster - G3 - Ward 3'!O20+'Roster - G4 - Services'!O20+'Roster - G5 - Mgmt'!O20 -> 0 | P20: ='Roster - G1 - RN'!P20+'Roster - G2 - Carer'!P20+'Roster - G3 - Ward 3'!P20+'Roster - G4 - Services'!P20+'Roster - G5 - Mgmt'!P20 -> 0 | Q20: ='Roster - G1 - RN'!Q20+'Roster - G2 - Carer'!Q20+'Roster - G3 - Ward 3'!Q20+'Roster - G4 - Services'!Q20+'Roster - G5 - Mgmt'!Q20 -> 0 | R20: ='Roster - G1 - RN'!R20+'Roster - G2 - Carer'!R20+'Roster - G3 - Ward 3'!R20+'Roster - G4 - Services'!R20+'Roster - G5 - Mgmt'!R20 -> 0 | T20: =SUM(L20:R20) -> 0 | V20: =IFERROR(W20/T20,0) -> 0 | W20: ='Roster - G1 - RN'!W20+'Roster - G2 - Carer'!W20+'Roster - G3 - Ward 3'!W20+'Roster - G4 - Services'!W20+'Roster - G5 - Mgmt'!W20 -> 0
A21: Laundry Staff | C21: LAUNDRY | L21: ='Roster - G1 - RN'!L21+'Roster - G2 - Carer'!L21+'Roster - G3 - Ward 3'!L21+'Roster - G4 - Services'!L21+'Roster - G5 - Mgmt'!L21 -> 0 | M21: ='Roster - G1 - RN'!M21+'Roster - G2 - Carer'!M21+'Roster - G3 - Ward 3'!M21+'Roster - G4 - Services'!M21+'Roster - G5 - Mgmt'!M21 -> 0 | N21: ='Roster - G1 - RN'!N21+'Roster - G2 - Carer'!N21+'Roster - G3 - Ward 3'!N21+'Roster - G4 - Services'!N21+'Roster - G5 - Mgmt'!N21 -> 0 | O21: ='Roster - G1 - RN'!O21+'Roster - G2 - Carer'!O21+'Roster - G3 - Ward 3'!O21+'Roster - G4 - Services'!O21+'Roster - G5 - Mgmt'!O21 -> 0 | P21: ='Roster - G1 - RN'!P21+'Roster - G2 - Carer'!P21+'Roster - G3 - Ward 3'!P21+'Roster - G4 - Services'!P21+'Roster - G5 - Mgmt'!P21 -> 0 | Q21: ='Roster - G1 - RN'!Q21+'Roster - G2 - Carer'!Q21+'Roster - G3 - Ward 3'!Q21+'Roster - G4 - Services'!Q21+'Roster - G5 - Mgmt'!Q21 -> 0 | R21: ='Roster - G1 - RN'!R21+'Roster - G2 - Carer'!R21+'Roster - G3 - Ward 3'!R21+'Roster - G4 - Services'!R21+'Roster - G5 - Mgmt'!R21 -> 0 | T21: =SUM(L21:R21) -> 0 | V21: =IFERROR(W21/T21,0) -> 0 | W21: ='Roster - G1 - RN'!W21+'Roster - G2 - Carer'!W21+'Roster - G3 - Ward 3'!W21+'Roster - G4 - Services'!W21+'Roster - G5 - Mgmt'!W21 -> 0
A22: Drivers | C22: DRIVER | L22: ='Roster - G1 - RN'!L22+'Roster - G2 - Carer'!L22+'Roster - G3 - Ward 3'!L22+'Roster - G4 - Services'!L22+'Roster - G5 - Mgmt'!L22 -> 0 | M22: ='Roster - G1 - RN'!M22+'Roster - G2 - Carer'!M22+'Roster - G3 - Ward 3'!M22+'Roster - G4 - Services'!M22+'Roster - G5 - Mgmt'!M22 -> 0 | N22: ='Roster - G1 - RN'!N22+'Roster - G2 - Carer'!N22+'Roster - G3 - Ward 3'!N22+'Roster - G4 - Services'!N22+'Roster - G5 - Mgmt'!N22 -> 0 | O22: ='Roster - G1 - RN'!O22+'Roster - G2 - Carer'!O22+'Roster - G3 - Ward 3'!O22+'Roster - G4 - Services'!O22+'Roster - G5 - Mgmt'!O22 -> 0 | P22: ='Roster - G1 - RN'!P22+'Roster - G2 - Carer'!P22+'Roster - G3 - Ward 3'!P22+'Roster - G4 - Services'!P22+'Roster - G5 - Mgmt'!P22 -> 0 | Q22: ='Roster - G1 - RN'!Q22+'Roster - G2 - Carer'!Q22+'Roster - G3 - Ward 3'!Q22+'Roster - G4 - Services'!Q22+'Roster - G5 - Mgmt'!Q22 -> 0 | R22: ='Roster - G1 - RN'!R22+'Roster - G2 - Carer'!R22+'Roster - G3 - Ward 3'!R22+'Roster - G4 - Services'!R22+'Roster - G5 - Mgmt'!R22 -> 0 | T22: =SUM(L22:R22) -> 0 | V22: =IFERROR(W22/T22,0) -> 0 | W22: ='Roster - G1 - RN'!W22+'Roster - G2 - Carer'!W22+'Roster - G3 - Ward 3'!W22+'Roster - G4 - Services'!W22+'Roster - G5 - Mgmt'!W22 -> 0
A24: MANAGEMENT & ADMIN | L24: =SUBTOTAL(9,L25:L27) -> 16 | M24: =SUBTOTAL(9,M25:M27) -> 16 | N24: =SUBTOTAL(9,N25:N27) -> 16 | O24: =SUBTOTAL(9,O25:O27) -> 16 | P24: =SUBTOTAL(9,P25:P27) -> 16 | Q24: =SUBTOTAL(9,Q25:Q27) -> 0 | R24: =SUBTOTAL(9,R25:R27) -> 0 | T24: =SUBTOTAL(9,T25:T27) -> 80 | V24: =IFERROR(W24/T24,0) -> 0.6 | W24: =SUBTOTAL(9,W25:W27) -> 48
A25: Clinical Managers | C25: CLINICAL MANAGEMENT | L25: ='Roster - G1 - RN'!L25+'Roster - G2 - Carer'!L25+'Roster - G3 - Ward 3'!L25+'Roster - G4 - Services'!L25+'Roster - G5 - Mgmt'!L25 -> 16 | M25: ='Roster - G1 - RN'!M25+'Roster - G2 - Carer'!M25+'Roster - G3 - Ward 3'!M25+'Roster - G4 - Services'!M25+'Roster - G5 - Mgmt'!M25 -> 16 | N25: ='Roster - G1 - RN'!N25+'Roster - G2 - Carer'!N25+'Roster - G3 - Ward 3'!N25+'Roster - G4 - Services'!N25+'Roster - G5 - Mgmt'!N25 -> 16 | O25: ='Roster - G1 - RN'!O25+'Roster - G2 - Carer'!O25+'Roster - G3 - Ward 3'!O25+'Roster - G4 - Services'!O25+'Roster - G5 - Mgmt'!O25 -> 16 | P25: ='Roster - G1 - RN'!P25+'Roster - G2 - Carer'!P25+'Roster - G3 - Ward 3'!P25+'Roster - G4 - Services'!P25+'Roster - G5 - Mgmt'!P25 -> 16 | Q25: ='Roster - G1 - RN'!Q25+'Roster - G2 - Carer'!Q25+'Roster - G3 - Ward 3'!Q25+'Roster - G4 - Services'!Q25+'Roster - G5 - Mgmt'!Q25 -> 0 | R25: ='Roster - G1 - RN'!R25+'Roster - G2 - Carer'!R25+'Roster - G3 - Ward 3'!R25+'Roster - G4 - Services'!R25+'Roster - G5 - Mgmt'!R25 -> 0 | T25: =SUM(L25:R25) -> 80 | V25: =IFERROR(W25/T25,0) -> 0.6 | W25: ='Roster - G1 - RN'!W25+'Roster - G2 - Carer'!W25+'Roster - G3 - Ward 3'!W25+'Roster - G4 - Services'!W25+'Roster - G5 - Mgmt'!W25 -> 48
A26: Administration | C26: NON-CLINICAL MANAGEMENT | L26: ='Roster - G1 - RN'!L26+'Roster - G2 - Carer'!L26+'Roster - G3 - Ward 3'!L26+'Roster - G4 - Services'!L26+'Roster - G5 - Mgmt'!L26 -> 0 | M26: ='Roster - G1 - RN'!M26+'Roster - G2 - Carer'!M26+'Roster - G3 - Ward 3'!M26+'Roster - G4 - Services'!M26+'Roster - G5 - Mgmt'!M26 -> 0 | N26: ='Roster - G1 - RN'!N26+'Roster - G2 - Carer'!N26+'Roster - G3 - Ward 3'!N26+'Roster - G4 - Services'!N26+'Roster - G5 - Mgmt'!N26 -> 0 | O26: ='Roster - G1 - RN'!O26+'Roster - G2 - Carer'!O26+'Roster - G3 - Ward 3'!O26+'Roster - G4 - Services'!O26+'Roster - G5 - Mgmt'!O26 -> 0 | P26: ='Roster - G1 - RN'!P26+'Roster - G2 - Carer'!P26+'Roster - G3 - Ward 3'!P26+'Roster - G4 - Services'!P26+'Roster - G5 - Mgmt'!P26 -> 0 | Q26: ='Roster - G1 - RN'!Q26+'Roster - G2 - Carer'!Q26+'Roster - G3 - Ward 3'!Q26+'Roster - G4 - Services'!Q26+'Roster - G5 - Mgmt'!Q26 -> 0 | R26: ='Roster - G1 - RN'!R26+'Roster - G2 - Carer'!R26+'Roster - G3 - Ward 3'!R26+'Roster - G4 - Services'!R26+'Roster - G5 - Mgmt'!R26 -> 0 | T26: =SUM(L26:R26) -> 0 | V26: =IFERROR(W26/T26,0) -> 0 | W26: ='Roster - G1 - RN'!W26+'Roster - G2 - Carer'!W26+'Roster - G3 - Ward 3'!W26+'Roster - G4 - Services'!W26+'Roster - G5 - Mgmt'!W26 -> 0

Sheet Roster - G1 - RN
A1: ='Primary Inputs'!$B$5 -> Christadelphian Aged Care
A3: Current Roster Budget
A5: Roster Code (in this model) | B5: Site(s) | C5: Wing | D5: Wing Type | E5: Maximum number of beds/licences
A6: ='Primary Inputs'!A9 -> G1 | B6: =VLOOKUP($A6,'Primary Inputs'!$A$9:$J$13,2,FALSE) -> Ashburn House | C6: =VLOOKUP($A6,'Primary Inputs'!$A$9:$J$13,3,FALSE) -> Used for RNs only | D6: =VLOOKUP($A6,'Primary Inputs'!$A$9:$J$13,4,FALSE) -> N/A | E6: =VLOOKUP($A6,'Primary Inputs'!$A$9:$J$13,5,FALSE) -> 99
L9: Roster Hours per Day | T9: Total Weekly Hours
A10: Location | B10: Shift | C10: Role | D10: Headcount per shift | E10: Notes | F10: Shift Start | G10: Shift End | H10: Shift Hours (Excl Break) | I10: Break | J10: Shift less breaks | K10: Total Hours | L10: Mon | M10: Tue | N10: Wed | O10: Thu | P10: Fri | Q10: Sat | R10: Sun | V10: AN-ACC Allocation (%) | W10: An-ACC Hours | Z10: Target | AB10: Variance
A12: ="TOTAL "&$C$6&" ROSTER" -> TOTAL Used for RNs only ROSTER | L12: =SUBTOTAL(9,L13:L28) -> 69.5 | M12: =SUBTOTAL(9,M13:M28) -> 77 | N12: =SUBTOTAL(9,N13:N28) -> 69.5 | O12: =SUBTOTAL(9,O13:O28) -> 69.5 | P12: =SUBTOTAL(9,P13:P28) -> 69.5 | Q12: =SUBTOTAL(9,Q13:Q28) -> 69.5 | R12: =SUBTOTAL(9,R13:R28) -> 69.5 | T12: =SUBTOTAL(9,T13:T28) -> 494 | V12: =IFERROR(W12/T12,0) -> 1 | W12: =SUBTOTAL(9,W13:W28) -> 494
A13: CARE ROSTER | L13: =SUBTOTAL(9,L14:L15) -> 69.5 | M13: =SUBTOTAL(9,M14:M15) -> 77 | N13: =SUBTOTAL(9,N14:N15) -> 69.5 | O13: =SUBTOTAL(9,O14:O15) -> 69.5 | P13: =SUBTOTAL(9,P14:P15) -> 69.5 | Q13: =SUBTOTAL(9,Q14:Q15) -> 69.5 | R13: =SUBTOTAL(9,R14:R15) -> 69.5 | T13: =SUBTOTAL(9,T14:T15) -> 494 | V13: =IFERROR(W13/T13,0) -> 1 | W13: =SUBTOTAL(9,W14:W15) -> 494
A14: Registered Nurses | C14: RN | L14: =SUMIF($C$30:$C$57,$C14,L$30:L$57) -> 69.5 | M14: =SUMIF($C$30:$C$57,$C14,M$30:M$57) -> 77 | N14: =SUMIF($C$30:$C$57,$C14,N$30:N$57) -> 69.5 | O14: =SUMIF($C$30:$C$57,$C14,O$30:O$57) -> 69.5 | P14: =SUMIF($C$30:$C$57,$C14,P$30:P$57) -> 69.5 | Q14: =SUMIF($C$30:$C$57,$C14,Q$30:Q$57) -> 69.5 | R14: =SUMIF($C$30:$C$57,$C14,R$30:R$57) -> 69.5 | T14: =SUM(L14:R14) -> 494 | V14: =IFERROR(W14/T14,0) -> 1 | W14: =SUMIFS(W$31:W$57,$C$31:$C$57,$C14) -> 494 | Z14: ='AN-ACC Simple'!I7*7 -> 512.82 | AB14: =W14-Z14 -> -18.82
A15: Carers and ENs | B15: RN Hours | C15: CARER | L15: =SUMIF($C$30:$C$57,$C15,L$30:L$57) -> 0 | M15: =SUMIF($C$30:$C$57,$C15,M$30:M$57) -> 0 | N15: =SUMIF($C$30:$C$57,$C15,N$30:N$57) -> 0 | O15: =SUMIF($C$30:$C$57,$C15,O$30:O$57) -> 0 | P15: =SUMIF($C$30:$C$57,$C15,P$30:P$57) -> 0 | Q15: =SUMIF($C$30:$C$57,$C15,Q$30:Q$57) -> 0 | R15: =SUMIF($C$30:$C$57,$C15,R$30:R$57) -> 0 | T15: =SUM(L15:R15) -> 0 | V15: =IFERROR(W15/T15,0) -> 0 | W15: =SUMIFS(W$31:W$57,$C$31:$C$57,$C15) -> 0
A17: LIFESTYLE | C17: LIFESTYLE | L17: =SUMIF($C$30:$C$57,$C17,L$30:L$57) -> 0 | M17: =SUMIF($C$30:$C$57,$C17,M$30:M$57) -> 0 | N17: =SUMIF($C$30:$C$57,$C17,N$30:N$57) -> 0 | O17: =SUMIF($C$30:$C$57,$C17,O$30:O$57) -> 0 | P17: =SUMIF($C$30:$C$57,$C17,P$30:P$57) -> 0 | Q17: =SUMIF($C$30:$C$57,$C17,Q$30:Q$57) -> 0 | R17: =SUMIF($C$30:$C$57,$C17,R$30:R$57) -> 0 | T17: =SUM(L17:R17) -> 0 | V17: =IFERROR(W17/T17,0) -> 0 | W17: =SUMIFS(W$31:W$57,$A$31:$A$57,$A17) -> 0
A19: KITCHEN & LAUNDRY | L19: =SUBTOTAL(9,L20:L23) -> 0 | M19: =SUBTOTAL(9,M20:M23) -> 0 | N19: =SUBTOTAL(9,N20:N23) -> 0 | O19: =SUBTOTAL(9,O20:O23) -> 0 | P19: =SUBTOTAL(9,P20:P23) -> 0 | Q19: =SUBTOTAL(9,Q20:Q23) -> 0 | R19: =SUBTOTAL(9,R20:R23) -> 0 | T19: =SUBTOTAL(9,T20:T23) -> 0 | V19: =IFERROR(W19/T19,0) -> 0 | W19: =SUBTOTAL(9,W20:W23) -> 0
A20: Chef, Kitchen Hand and Servery | C20: KITCHEN | L20: =SUMIF($C$30:$C$57,$C20,L$30:L$57) -> 0 | M20: =SUMIF($C$30:$C$57,$C20,M$30:M$57) -> 0 | N20: =SUMIF($C$30:$C$57,$C20,N$30:N$57) -> 0 | O20: =SUMIF($C$30:$C$57,$C20,O$30:O$57) -> 0 | P20: =SUMIF($C$30:$C$57,$C20,P$30:P$57) -> 0 | Q20: =SUMIF($C$30:$C$57,$C20,Q$30:Q$57) -> 0 | R20: =SUMIF($C$30:$C$57,$C20,R$30:R$57) -> 0 | T20: =SUM(L20:R20) -> 0 | V20: =IFERROR(W20/T20,0) -> 0 | W20: =SUMIFS(W$31:W$57,$C$31:$C$57,$C20) -> 0
A21: Laundry Staff | C21: LAUNDRY | L21: =SUMIF($C$30:$C$57,$C21,L$30:L$57) -> 0 | M21: =SUMIF($C$30:$C$57,$C21,M$30:M$57) -> 0 | N21: =SUMIF($C$30:$C$57,$C21,N$30:N$57) -> 0 | O21: =SUMIF($C$30:$C$57,$C21,O$30:O$57) -> 0 | P21: =SUMIF($C$30:$C$57,$C21,P$30:P$57) -> 0 | Q21: =SUMIF($C$30:$C$57,$C21,Q$30:Q$57) -> 0 | R21: =SUMIF($C$30:$C$57,$C21,R$30:R$57) -> 0 | T21: =SUM(L21:R21) -> 0 | V21: =IFERROR(W21/T21,0) -> 0 | W21: =SUMIFS(W$31:W$57,$C$31:$C$57,$C21) -> 0
A22: Drivers | C22: DRIVER | L22: =SUMIF($C$30:$C$57,$C22,L$30:L$57) -> 0 | M22: =SUMIF($C$30:$C$57,$C22,M$30:M$57) -> 0 | N22: =SUMIF($C$30:$C$57,$C22,N$30:N$57) -> 0 | O22: =SUMIF($C$30:$C$57,$C22,O$30:O$57) -> 0 | P22: =SUMIF($C$30:$C$57,$C22,P$30:P$57) -> 0 | Q22: =SUMIF($C$30:$C$57,$C22,Q$30:Q$57) -> 0 | R22: =SUMIF($C$30:$C$57,$C22,R$30:R$57) -> 0 | T22: =SUM(L22:R22) -> 0 | V22: =IFERROR(W22/T22,0) -> 0 | W22: =SUMIFS(W$31:W$57,$C$31:$C$57,$C22) -> 0
A24: MANAGEMENT & ADMIN | L24: =SUBTOTAL(9,L25:L27) -> 0 | M24: =SUBTOTAL(9,M25:M27) -> 0 | N24: =SUBTOTAL(9,N25:N27) -> 0 | O24: =SUBTOTAL(9,O25:O27) -> 0 | P24: =SUBTOTAL(9,P25:P27) -> 0 | Q24: =SUBTOTAL(9,Q25:Q27) -> 0 | R24: =SUBTOTAL(9,R25:R27) -> 0 | T24: =SUBTOTAL(9,T25:T27) -> 0 | V24: =IFERROR(W24/T24,0) -> 0 | W24: =SUBTOTAL(9,W25:W27) -> 0
A25: Facility Manager | C25: CLINICAL MANAGEMENT | L25: =SUMIF($C$30:$C$57,$C25,L$30:L$57) -> 0 | M25: =SUMIF($C$30:$C$57,$C25,M$30:M$57) -> 0 | N25: =SUMIF($C$30:$C$57,$C25,N$30:N$57) -> 0 | O25: =SUMIF($C$30:$C$57,$C25,O$30:O$57) -> 0 | P25: =SUMIF($C$30:$C$57,$C25,P$30:P$57) -> 0 | Q25: =SUMIF($C$30:$C$57,$C25,Q$30:Q$57) -> 0 | R25: =SUMIF($C$30:$C$57,$C25,R$30:R$57) -> 0 | T25: =SUM(L25:R25) -> 0 | V25: =IFERROR(W25/T25,0) -> 0 | W25: =SUMIFS(W$31:W$57,$C$31:$C$57,$C25) -> 0
A26: Care Manager | C26: NON-CLINICAL MANAGEMENT | L26: =SUMIF($C$30:$C$57,$C26,L$30:L$57) -> 0 | M26: =SUMIF($C$30:$C$57,$C26,M$30:M$57) -> 0 | N26: =SUMIF($C$30:$C$57,$C26,N$30:N$57) -> 0 | O26: =SUMIF($C$30:$C$57,$C26,O$30:O$57) -> 0 | P26: =SUMIF($C$30:$C$57,$C26,P$30:P$57) -> 0 | Q26: =SUMIF($C$30:$C$57,$C26,Q$30:Q$57) -> 0 | R26: =SUMIF($C$30:$C$57,$C26,R$30:R$57) -> 0 | T26: =SUM(L26:R26) -> 0 | V26: =IFERROR(W26/T26,0) -> 0 | W26: =SUMIFS(W$31:W$57,$C$31:$C$57,$C26) -> 0
A30: ROLE | B30: SHIFT TIME | C30: AN-ACC ALLOCATION | D30: COUNT | F30: START | G30: END | H30: Raw Time | I30: Less break | J30: Paid time | K30: Total per head count | L30: =SUBTOTAL(9,L31:L57) -> 69.5 | M30: =SUBTOTAL(9,M31:M57) -> 77 | N30: =SUBTOTAL(9,N31:N57) -> 69.5 | O30: =SUBTOTAL(9,O31:O57) -> 69.5 | P30: =SUBTOTAL(9,P31:P57) -> 69.5 | Q30: =SUBTOTAL(9,Q31:Q57) -> 69.5 | R30: =SUBTOTAL(9,R31:R57) -> 69.5 | T30: =SUBTOTAL(9,T31:T57) -> 494 | W30: =SUBTOTAL(9,W31:W57) -> 494
A31: Morning RN | B31: AM | C31: RN | D31: 5 | F31: 0.29166667 | G31: 0.625 | H31: =IF((G31-F31)<0,(G31+(1-F31))*24,(G31-F31)*24) -> 8 | I31: =IF(H31>5,-0.5,0) -> -0.5 | J31: =SUM(H31:I31) -> 7.5 | K31: =D31*J31 -> 37.5 | L31: =$K31 -> 37.5 | M31: =$K31 -> 37.5 | N31: =$K31 -> 37.5 | O31: =$K31 -> 37.5 | P31: =$K31 -> 37.5 | Q31: =$K31 -> 37.5 | R31: =$K31 -> 37.5 | T31: =SUM(L31:S31) -> 262.5 | V31: 1 | W31: =T31*V31 -> 262.5
A32: Infection Control | B32: AM | C32: RN | D32: 1 | F32: 0.33333333 | G32: 0.66666667 | H32: =IF((G32-F32)<0,(G32+(1-F32))*24,(G32-F32)*24) -> 8 | I32: =IF(H32>5,-0.5,0) -> -0.5 | J32: =SUM(H32:I32) -> 7.5 | K32: =D32*J32 -> 7.5 | M32: =$K32 -> 7.5 | T32: =SUM(L32:S32) -> 7.5 | V32: 1 | W32: =T32*V32 -> 7.5
T33: =SUM(L33:S33) -> 0 | V33: 1 | W33: =T33*V33 -> 0
A34: Afternoon RN | B34: PM | C34: RN | D34: 3 | F34: 0.60416667 | G34: 0.95833333 | H34: =IF((G34-F34)<0,(G34+(1-F34))*24,(G34-F34)*24) -> 8.5 | I34: =IF(H34>5,-0.5,0) -> -0.5 | J34: =SUM(H34:I34) -> 8 | K34: =D34*J34 -> 24 | L34: =$K34 -> 24 | M34: =$K34 -> 24 | N34: =$K34 -> 24 | O34: =$K34 -> 24 | P34: =$K34 -> 24 | Q34: =$K34 -> 24 | R34: =$K34 -> 24 | T34: =SUM(L34:S34) -> 168 | V34: 1 | W34: =T34*V34 -> 168
T35: =SUM(L35:S35) -> 0 | V35: 1 | W35: =T35*V35 -> 0
T36: =SUM(L36:S36) -> 0 | V36: 1 | W36: =T36*V36 -> 0
A37: NIGHT In Charge | B37: NIGHT | C37: RN | D37: 1 | F37: 0.94791667 | G37: 0.30208333 | H37: =IF((G37-F37)<0,(G37+(1-F37))*24,(G37-F37)*24) -> 8.5 | I37: =IF(H37>5,-0.5,0) -> -0.5 | J37: =SUM(H37:I37) -> 8 | K37: =D37*J37 -> 8 | L37: =$K37 -> 8 | M37: =$K37 -> 8 | N37: =$K37 -> 8 | O37: =$K37 -> 8 | P37: =$K37 -> 8 | Q37: =$K37 -> 8 | R37: =$K37 -> 8 | T37: =SUM(L37:S37) -> 56 | V37: 1 | W37: =T37*V37 -> 56
V38: 1 | W38: =T38*V38 -> 0
V39: 1 | W39: =T39*V39 -> 0
V40: 1 | W40: =T40*V40 -> 0
V41: =IFERROR(VLOOKUP(A41,#REF!,4,FALSE),0) -> 0 | W41: =T41*V41 -> 0
V42: =IFERROR(VLOOKUP(A42,#REF!,4,FALSE),0) -> 0 | W42: =T42*V42 -> 0
V43: =IFERROR(VLOOKUP(A43,#REF!,4,FALSE),0) -> 0 | W43: =T43*V43 -> 0
V44: =IFERROR(VLOOKUP(A44,#REF!,4,FALSE),0) -> 0 | W44: =T44*V44 -> 0
V45: =IFERROR(VLOOKUP(A45,#REF!,4,FALSE),0) -> 0 | W45: =T45*V45 -> 0
V46: =IFERROR(VLOOKUP(A46,#REF!,4,FALSE),0) -> 0 | W46: =T46*V46 -> 0
V47: =IFERROR(VLOOKUP(A47,#REF!,4,FALSE),0) -> 0 | W47: =T47*V47 -> 0
V48: =IFERROR(VLOOKUP(A48,#REF!,4,FALSE),0) -> 0 | W48: =T48*V48 -> 0
V49: =IFERROR(VLOOKUP(A49,#REF!,4,FALSE),0) -> 0 | W49: =T49*V49 -> 0
V50: =IFERROR(VLOOKUP(A50,#REF!,4,FALSE),0) -> 0 | W50: =T50*V50 -> 0
V51: =IFERROR(VLOOKUP(A51,#REF!,4,FALSE),0) -> 0 | W51: =T51*V51 -> 0
...

Sheet Roster - G2 - Carer
A1: ='Primary Inputs'!$B$5 -> Christadelphian Aged Care
A3: Current Roster Budget
A5: Roster Code (in this model) | B5: Site(s) | C5: Wing | D5: Wing Type | E5: Maximum number of beds/licences
A6: ='Primary Inputs'!A10 -> G2 | B6: =VLOOKUP($A6,'Primary Inputs'!$A$9:$J$13,2,FALSE) -> Ashburn House | C6: =VLOOKUP($A6,'Primary Inputs'!$A$9:$J$13,3,FALSE) -> Used for Carers Only | D6: =VLOOKUP($A6,'Primary Inputs'!$A$9:$J$13,4,FALSE) -> N/A | E6: =VLOOKUP($A6,'Primary Inputs'!$A$9:$J$13,5,FALSE) -> 0
L9: Roster Hours per Day | T9: Total Weekly Hours
A10: Location | B10: Shift | C10: Role | D10: Headcount per shift | E10: Notes | F10: Shift Start | G10: Shift End | H10: Shift Hours (Excl Break) | I10: Break | J10: Shift less breaks | K10: Total Hours | L10: Mon | M10: Tue | N10: Wed | O10: Thu | P10: Fri | Q10: Sat | R10: Sun | V10: AN-ACC Allocation (%) | W10: An-ACC Hours | Z10: Target | AB10: Variance
A12: ="TOTAL "&$C$6&" ROSTER" -> TOTAL Used for Carers Only ROSTER | L12: =SUBTOTAL(9,L13:L28) -> 311 | M12: =SUBTOTAL(9,M13:M28) -> 311 | N12: =SUBTOTAL(9,N13:N28) -> 311 | O12: =SUBTOTAL(9,O13:O28) -> 311 | P12: =SUBTOTAL(9,P13:P28) -> 311 | Q12: =SUBTOTAL(9,Q13:Q28) -> 311 | R12: =SUBTOTAL(9,R13:R28) -> 311 | T12: =SUBTOTAL(9,T13:T28) -> 2177 | V12: =IFERROR(W12/T12,0) -> 1 | W12: =SUBTOTAL(9,W13:W28) -> 2177
A13: CARE ROSTER | L13: =SUBTOTAL(9,L14:L15) -> 311 | M13: =SUBTOTAL(9,M14:M15) -> 311 | N13: =SUBTOTAL(9,N14:N15) -> 311 | O13: =SUBTOTAL(9,O14:O15) -> 311 | P13: =SUBTOTAL(9,P14:P15) -> 311 | Q13: =SUBTOTAL(9,Q14:Q15) -> 311 | R13: =SUBTOTAL(9,R14:R15) -> 311 | T13: =SUBTOTAL(9,T14:T15) -> 2177 | V13: =IFERROR(W13/T13,0) -> 1 | W13: =SUBTOTAL(9,W14:W15) -> 2177
A14: Registered Nurses | C14: RN | L14: =SUMIF($C$30:$C$71,$C14,L$30:L$71) -> 0 | M14: =SUMIF($C$30:$C$71,$C14,M$30:M$71) -> 0 | N14: =SUMIF($C$30:$C$71,$C14,N$30:N$71) -> 0 | O14: =SUMIF($C$30:$C$71,$C14,O$30:O$71) -> 0 | P14: =SUMIF($C$30:$C$71,$C14,P$30:P$71) -> 0 | Q14: =SUMIF($C$30:$C$71,$C14,Q$30:Q$71) -> 0 | R14: =SUMIF($C$30:$C$71,$C14,R$30:R$71) -> 0 | T14: =SUM(L14:R14) -> 0 | V14: =IFERROR(W14/T14,0) -> 0 | W14: =SUMIFS(W$31:W$71,$C$31:$C$71,$C14) -> 0
A15: Carers and ENs | B15: RN Hours | C15: CARER | L15: =SUMIF($C$30:$C$71,$C15,L$30:L$71) -> 311 | M15: =SUMIF($C$30:$C$71,$C15,M$30:M$71) -> 311 | N15: =SUMIF($C$30:$C$71,$C15,N$30:N$71) -> 311 | O15: =SUMIF($C$30:$C$71,$C15,O$30:O$71) -> 311 | P15: =SUMIF($C$30:$C$71,$C15,P$30:P$71) -> 311 | Q15: =SUMIF($C$30:$C$71,$C15,Q$30:Q$71) -> 311 | R15: =SUMIF($C$30:$C$71,$C15,R$30:R$71) -> 311 | T15: =SUM(L15:R15) -> 2177 | V15: =IFERROR(W15/T15,0) -> 1 | W15: =SUMIFS(W$31:W$71,$C$31:$C$71,$C15) -> 2177 | Z15: =('AN-ACC Simple'!E7-'AN-ACC Simple'!I7)*7 -> 1998.381 | AB15: =T15-Z15 -> 178.619
A17: LIFESTYLE | C17: LIFESTYLE | L17: =SUMIF($C$30:$C$71,$C17,L$30:L$71) -> 0 | M17: =SUMIF($C$30:$C$71,$C17,M$30:M$71) -> 0 | N17: =SUMIF($C$30:$C$71,$C17,N$30:N$71) -> 0 | O17: =SUMIF($C$30:$C$71,$C17,O$30:O$71) -> 0 | P17: =SUMIF($C$30:$C$71,$C17,P$30:P$71) -> 0 | Q17: =SUMIF($C$30:$C$71,$C17,Q$30:Q$71) -> 0 | R17: =SUMIF($C$30:$C$71,$C17,R$30:R$71) -> 0 | T17: =SUM(L17:R17) -> 0 | V17: =IFERROR(W17/T17,0) -> 0 | W17: =SUMIFS(W$31:W$71,$A$31:$A$71,$A17) -> 0
A19: KITCHEN & LAUNDRY | L19: =SUBTOTAL(9,L20:L23) -> 0 | M19: =SUBTOTAL(9,M20:M23) -> 0 | N19: =SUBTOTAL(9,N20:N23) -> 0 | O19: =SUBTOTAL(9,O20:O23) -> 0 | P19: =SUBTOTAL(9,P20:P23) -> 0 | Q19: =SUBTOTAL(9,Q20:Q23) -> 0 | R19: =SUBTOTAL(9,R20:R23) -> 0 | T19: =SUBTOTAL(9,T20:T23) -> 0 | V19: =IFERROR(W19/T19,0) -> 0 | W19: =SUBTOTAL(9,W20:W23) -> 0
A20: Chef, Kitchen Hand and Servery | C20: KITCHEN | L20: =SUMIF($C$30:$C$71,$C20,L$30:L$71) -> 0 | M20: =SUMIF($C$30:$C$71,$C20,M$30:M$71) -> 0 | N20: =SUMIF($C$30:$C$71,$C20,N$30:N$71) -> 0 | O20: =SUMIF($C$30:$C$71,$C20,O$30:O$71) -> 0 | P20: =SUMIF($C$30:$C$71,$C20,P$30:P$71) -> 0 | Q20: =SUMIF($C$30:$C$71,$C20,Q$30:Q$71) -> 0 | R20: =SUMIF($C$30:$C$71,$C20,R$30:R$71) -> 0 | T20: =SUM(L20:R20) -> 0 | V20: =IFERROR(W20/T20,0) -> 0 | W20: =SUMIFS(W$31:W$71,$C$31:$C$71,$C20) -> 0
A21: Laundry Staff | C21: LAUNDRY | L21: =SUMIF($C$30:$C$71,$C21,L$30:L$71) -> 0 | M21: =SUMIF($C$30:$C$71,$C21,M$30:M$71) -> 0 | N21: =SUMIF($C$30:$C$71,$C21,N$30:N$71) -> 0 | O21: =SUMIF($C$30:$C$71,$C21,O$30:O$71) -> 0 | P21: =SUMIF($C$30:$C$71,$C21,P$30:P$71) -> 0 | Q21: =SUMIF($C$30:$C$71,$C21,Q$30:Q$71) -> 0 | R21: =SUMIF($C$30:$C$71,$C21,R$30:R$71) -> 0 | T21: =SUM(L21:R21) -> 0 | V21: =IFERROR(W21/T21,0) -> 0 | W21: =SUMIFS(W$31:W$71,$C$31:$C$71,$C21) -> 0
A22: Drivers | C22: DRIVER | L22: =SUMIF($C$30:$C$71,$C22,L$30:L$71) -> 0 | M22: =SUMIF($C$30:$C$71,$C22,M$30:M$71) -> 0 | N22: =SUMIF($C$30:$C$71,$C22,N$30:N$71) -> 0 | O22: =SUMIF($C$30:$C$71,$C22,O$30:O$71) -> 0 | P22: =SUMIF($C$30:$C$71,$C22,P$30:P$71) -> 0 | Q22: =SUMIF($C$30:$C$71,$C22,Q$30:Q$71) -> 0 | R22: =SUMIF($C$30:$C$71,$C22,R$30:R$71) -> 0 | T22: =SUM(L22:R22) -> 0 | V22: =IFERROR(W22/T22,0) -> 0 | W22: =SUMIFS(W$31:W$71,$C$31:$C$71,$C22) -> 0
A24: MANAGEMENT & ADMIN | L24: =SUBTOTAL(9,L25:L27) -> 0 | M24: =SUBTOTAL(9,M25:M27) -> 0 | N24: =SUBTOTAL(9,N25:N27) -> 0 | O24: =SUBTOTAL(9,O25:O27) -> 0 | P24: =SUBTOTAL(9,P25:P27) -> 0 | Q24: =SUBTOTAL(9,Q25:Q27) -> 0 | R24: =SUBTOTAL(9,R25:R27) -> 0 | T24: =SUBTOTAL(9,T25:T27) -> 0 | V24: =IFERROR(W24/T24,0) -> 0 | W24: =SUBTOTAL(9,W25:W27) -> 0
A25: Facility Manager | C25: CLINICAL MANAGEMENT | L25: =SUMIF($C$30:$C$71,$C25,L$30:L$71) -> 0 | M25: =SUMIF($C$30:$C$71,$C25,M$30:M$71) -> 0 | N25: =SUMIF($C$30:$C$71,$C25,N$30:N$71) -> 0 | O25: =SUMIF($C$30:$C$71,$C25,O$30:O$71) -> 0 | P25: =SUMIF($C$30:$C$71,$C25,P$30:P$71) -> 0 | Q25: =SUMIF($C$30:$C$71,$C25,Q$30:Q$71) -> 0 | R25: =SUMIF($C$30:$C$71,$C25,R$30:R$71) -> 0 | T25: =SUM(L25:R25) -> 0 | V25: =IFERROR(W25/T25,0) -> 0 | W25: =SUMIFS(W$31:W$71,$C$31:$C$71,$C25) -> 0
A26: Care Manager | C26: NON-CLINICAL MANAGEMENT | L26: =SUMIF($C$30:$C$71,$C26,L$30:L$71) -> 0 | M26: =SUMIF($C$30:$C$71,$C26,M$30:M$71) -> 0 | N26: =SUMIF($C$30:$C$71,$C26,N$30:N$71) -> 0 | O26: =SUMIF($C$30:$C$71,$C26,O$30:O$71) -> 0 | P26: =SUMIF($C$30:$C$71,$C26,P$30:P$71) -> 0 | Q26: =SUMIF($C$30:$C$71,$C26,Q$30:Q$71) -> 0 | R26: =SUMIF($C$30:$C$71,$C26,R$30:R$71) -> 0 | T26: =SUM(L26:R26) -> 0 | V26: =IFERROR(W26/T26,0) -> 0 | W26: =SUMIFS(W$31:W$71,$C$31:$C$71,$C26) -> 0
A30: ROLE | B30: SHIFT TIME | C30: AN-ACC ALLOCATION | D30: COUNT | F30: START | G30: END | H30: Raw Time | I30: Less break | J30: Paid time | K30: Total per head count | L30: =SUBTOTAL(9,L31:L71) -> 311 | M30: =SUBTOTAL(9,M31:M71) -> 311 | N30: =SUBTOTAL(9,N31:N71) -> 311 | O30: =SUBTOTAL(9,O31:O71) -> 311 | P30: =SUBTOTAL(9,P31:P71) -> 311 | Q30: =SUBTOTAL(9,Q31:Q71) -> 311 | R30: =SUBTOTAL(9,R31:R71) -> 311 | T30: =SUBTOTAL(9,T31:T71) -> 2177 | W30: =SUBTOTAL(9,W31:W71) -> 2177
A31: Cert4 Meds Comp | B31: AM | C31: CARER | D31: 3 | F31: 0.29166667 | G31: 0.625 | H31: =IF((G31-F31)<0,(G31+(1-F31))*24,(G31-F31)*24) -> 8 | I31: =IF(H31>5,-0.5,0) -> -0.5 | J31: =SUM(H31:I31) -> 7.5 | K31: =D31*J31 -> 22.5 | L31: =$K31 -> 22.5 | M31: =$K31 -> 22.5 | N31: =$K31 -> 22.5 | O31: =$K31 -> 22.5 | P31: =$K31 -> 22.5 | Q31: =$K31 -> 22.5 | R31: =$K31 -> 22.5 | T31: =SUM(L31:S31) -> 157.5 | V31: 1 | W31: =T31*V31 -> 157.5
A32: Carer - Stnd Shift | B32: AM | C32: CARER | D32: 17 | F32: 0.29166667 | G32: 0.625 | H32: =IF((G32-F32)<0,(G32+(1-F32))*24,(G32-F32)*24) -> 8 | I32: =IF(H32>5,-0.5,0) -> -0.5 | J32: =SUM(H32:I32) -> 7.5 | K32: =D32*J32 -> 127.5 | L32: =$K32 -> 127.5 | M32: =$K32 -> 127.5 | N32: =$K32 -> 127.5 | O32: =$K32 -> 127.5 | P32: =$K32 -> 127.5 | Q32: =$K32 -> 127.5 | R32: =$K32 -> 127.5 | T32: =SUM(L32:S32) -> 892.5 | V32: 1 | W32: =T32*V32 -> 892.5
A33: Carer - Short Shift | B33: AM | C33: CARER | D33: 2 | F33: 0.29166667 | G33: 0.47916667 | H33: =IF((G33-F33)<0,(G33+(1-F33))*24,(G33-F33)*24) -> 4.5 | I33: =IF(H33>5,-0.5,0) -> 0 | J33: =SUM(H33:I33) -> 4.5 | K33: =D33*J33 -> 9 | L33: =$K33 -> 9 | M33: =$K33 -> 9 | N33: =$K33 -> 9 | O33: =$K33 -> 9 | P33: =$K33 -> 9 | Q33: =$K33 -> 9 | R33: =$K33 -> 9 | T33: =SUM(L33:S33) -> 63 | V33: 1 | W33: =T33*V33 -> 63
W34: =T34*V34 -> 0
A35: Cert4 Meds Comp | B35: PM | C35: CARER | D35: 3 | F35: 0.60416667 | G35: 0.95833333 | H35: =IF((G35-F35)<0,(G35+(1-F35))*24,(G35-F35)*24) -> 8.5 | I35: =IF(H35>5,-0.5,0) -> -0.5 | J35: =SUM(H35:I35) -> 8 | K35: =D35*J35 -> 24 | L35: =$K35 -> 24 | M35: =$K35 -> 24 | N35: =$K35 -> 24 | O35: =$K35 -> 24 | P35: =$K35 -> 24 | Q35: =$K35 -> 24 | R35: =$K35 -> 24 | T35: =SUM(L35:S35) -> 168 | V35: 1 | W35: =T35*V35 -> 168
A36: Carer - Stnd Shift | B36: PM | C36: CARER | D36: 9 | F36: 0.60416667 | G36: 0.875 | H36: =IF((G36-F36)<0,(G36+(1-F36))*24,(G36-F36)*24) -> 6.5 | I36: =IF(H36>5,-0.5,0) -> -0.5 | J36: =SUM(H36:I36) -> 6 | K36: =D36*J36 -> 54 | L36: =$K36 -> 54 | M36: =$K36 -> 54 | N36: =$K36 -> 54 | O36: =$K36 -> 54 | P36: =$K36 -> 54 | Q36: =$K36 -> 54 | R36: =$K36 -> 54 | T36: =SUM(L36:S36) -> 378 | V36: 1 | W36: =T36*V36 -> 378
A37: Carer - Short Shift | B37: PM | C37: CARER | D37: 2 | F37: 0.60416667 | G37: 0.8125 | H37: =IF((G37-F37)<0,(G37+(1-F37))*24,(G37-F37)*24) -> 5 | I37: =IF(H37>5,-0.5,0) -> 0 | J37: =SUM(H37:I37) -> 5 | K37: =D37*J37 -> 10 | L37: =$K37 -> 10 | M37: =$K37 -> 10 | N37: =$K37 -> 10 | O37: =$K37 -> 10 | P37: =$K37 -> 10 | Q37: =$K37 -> 10 | R37: =$K37 -> 10 | T37: =SUM(L37:S37) -> 70 | V37: 1 | W37: =T37*V37 -> 70
W38: =T38*V38 -> 0
A39: Cert4 Meds Comp | B39: NIGHT | C39: CARER | D39: 2 | F39: 0.94791667 | G39: 0.30208333 | H39: =IF((G39-F39)<0,(G39+(1-F39))*24,(G39-F39)*24) -> 8.5 | I39: =IF(H39>5,-0.5,0) -> -0.5 | J39: =SUM(H39:I39) -> 8 | K39: =D39*J39 -> 16 | L39: =$K39 -> 16 | M39: =$K39 -> 16 | N39: =$K39 -> 16 | O39: =$K39 -> 16 | P39: =$K39 -> 16 | Q39: =$K39 -> 16 | R39: =$K39 -> 16 | T39: =SUM(L39:S39) -> 112 | V39: 1 | W39: =T39*V39 -> 112
A40: Carer - Stnd Shift | B40: NIGHT | C40: CARER | D40: 6 | F40: 0.94791667 | G40: 0.30208333 | H40: =IF((G40-F40)<0,(G40+(1-F40))*24,(G40-F40)*24) -> 8.5 | I40: =IF(H40>5,-0.5,0) -> -0.5 | J40: =SUM(H40:I40) -> 8 | K40: =D40*J40 -> 48 | L40: =$K40 -> 48 | M40: =$K40 -> 48 | N40: =$K40 -> 48 | O40: =$K40 -> 48 | P40: =$K40 -> 48 | Q40: =$K40 -> 48 | R40: =$K40 -> 48 | T40: =SUM(L40:S40) -> 336 | V40: 1 | W40: =T40*V40 -> 336
W41: =T41*V41 -> 0
W42: =T42*V42 -> 0
W43: =T43*V43 -> 0
W44: =T44*V44 -> 0
W45: =T45*V45 -> 0
W46: =T46*V46 -> 0
W47: =T47*V47 -> 0
W48: =T48*V48 -> 0
W49: =T49*V49 -> 0
W50: =T50*V50 -> 0
W51: =T51*V51 -> 0
...

Sheet Roster - G3 - Ward 3
A1: ='Primary Inputs'!$B$5 -> Christadelphian Aged Care
A3: Current Roster Budget
A5: Roster Code (in this model) | B5: Site(s) | C5: Wing | D5: Wing Type | E5: Maximum number of beds/licences
A6: ='Primary Inputs'!A11 -> G3 | B6: =VLOOKUP($A6,'Primary Inputs'!$A$9:$J$13,2,FALSE) -> Ashburn House | C6: =VLOOKUP($A6,'Primary Inputs'!$A$9:$J$13,3,FALSE) -> Hidden | D6: =VLOOKUP($A6,'Primary Inputs'!$A$9:$J$13,4,FALSE) -> N/A | E6: =VLOOKUP($A6,'Primary Inputs'!$A$9:$J$13,5,FALSE) -> 0
L9: Roster Hours per Day | T9: Total Weekly Hours
A10: Location | B10: Shift | C10: Role | D10: Headcount per shift | E10: Notes | F10: Shift Start | G10: Shift End | H10: Shift Hours (Excl Break) | I10: Break | J10: Shift less breaks | K10: Total Hours | L10: Mon | M10: Tue | N10: Wed | O10: Thu | P10: Fri | Q10: Sat | R10: Sun | V10: AN-ACC Allocation (%) | W10: An-ACC Hours
A12: ="TOTAL "&$C$6&" ROSTER" -> TOTAL Hidden ROSTER | L12: =SUBTOTAL(9,L13:L28) -> 0 | M12: =SUBTOTAL(9,M13:M28) -> 0 | N12: =SUBTOTAL(9,N13:N28) -> 0 | O12: =SUBTOTAL(9,O13:O28) -> 0 | P12: =SUBTOTAL(9,P13:P28) -> 0 | Q12: =SUBTOTAL(9,Q13:Q28) -> 0 | R12: =SUBTOTAL(9,R13:R28) -> 0 | T12: =SUBTOTAL(9,T13:T28) -> 0 | V12: =IFERROR(W12/T12,0) -> 0 | W12: =SUBTOTAL(9,W13:W28) -> 0
A13: CARE ROSTER | L13: =SUBTOTAL(9,L14:L15) -> 0 | M13: =SUBTOTAL(9,M14:M15) -> 0 | N13: =SUBTOTAL(9,N14:N15) -> 0 | O13: =SUBTOTAL(9,O14:O15) -> 0 | P13: =SUBTOTAL(9,P14:P15) -> 0 | Q13: =SUBTOTAL(9,Q14:Q15) -> 0 | R13: =SUBTOTAL(9,R14:R15) -> 0 | T13: =SUBTOTAL(9,T14:T15) -> 0 | V13: =IFERROR(W13/T13,0) -> 0 | W13: =SUBTOTAL(9,W14:W15) -> 0
A14: Registered Nurses | C14: RN | L14: =SUMIF($C$30:$C$71,$C14,L$30:L$71) -> 0 | M14: =SUMIF($C$30:$C$71,$C14,M$30:M$71) -> 0 | N14: =SUMIF($C$30:$C$71,$C14,N$30:N$71) -> 0 | O14: =SUMIF($C$30:$C$71,$C14,O$30:O$71) -> 0 | P14: =SUMIF($C$30:$C$71,$C14,P$30:P$71) -> 0 | Q14: =SUMIF($C$30:$C$71,$C14,Q$30:Q$71) -> 0 | R14: =SUMIF($C$30:$C$71,$C14,R$30:R$71) -> 0 | T14: =SUM(L14:R14) -> 0 | V14: =IFERROR(W14/T14,0) -> 0 | W14: =SUMIFS(W$31:W$71,$C$31:$C$71,$C14) -> 0
A15: Carers and ENs | B15: RN Hours | C15: CARER | L15: =SUMIF($C$30:$C$71,$C15,L$30:L$71) -> 0 | M15: =SUMIF($C$30:$C$71,$C15,M$30:M$71) -> 0 | N15: =SUMIF($C$30:$C$71,$C15,N$30:N$71) -> 0 | O15: =SUMIF($C$30:$C$71,$C15,O$30:O$71) -> 0 | P15: =SUMIF($C$30:$C$71,$C15,P$30:P$71) -> 0 | Q15: =SUMIF($C$30:$C$71,$C15,Q$30:Q$71) -> 0 | R15: =SUMIF($C$30:$C$71,$C15,R$30:R$71) -> 0 | T15: =SUM(L15:R15) -> 0 | V15: =IFERROR(W15/T15,0) -> 0 | W15: =SUMIFS(W$31:W$71,$C$31:$C$71,$C15) -> 0
A17: LIFESTYLE | C17: LIFESTYLE | L17: =SUMIF($C$30:$C$71,$C17,L$30:L$71) -> 0 | M17: =SUMIF($C$30:$C$71,$C17,M$30:M$71) -> 0 | N17: =SUMIF($C$30:$C$71,$C17,N$30:N$71) -> 0 | O17: =SUMIF($C$30:$C$71,$C17,O$30:O$71) -> 0 | P17: =SUMIF($C$30:$C$71,$C17,P$30:P$71) -> 0 | Q17: =SUMIF($C$30:$C$71,$C17,Q$30:Q$71) -> 0 | R17: =SUMIF($C$30:$C$71,$C17,R$30:R$71) -> 0 | T17: =SUM(L17:R17) -> 0 | V17: =IFERROR(W17/T17,0) -> 0 | W17: =SUMIFS(W$31:W$71,$A$31:$A$71,$A17) -> 0
A19: KITCHEN & LAUNDRY | L19: =SUBTOTAL(9,L20:L23) -> 0 | M19: =SUBTOTAL(9,M20:M23) -> 0 | N19: =SUBTOTAL(9,N20:N23) -> 0 | O19: =SUBTOTAL(9,O20:O23) -> 0 | P19: =SUBTOTAL(9,P20:P23) -> 0 | Q19: =SUBTOTAL(9,Q20:Q23) -> 0 | R19: =SUBTOTAL(9,R20:R23) -> 0 | T19: =SUBTOTAL(9,T20:T23) -> 0 | V19: =IFERROR(W19/T19,0) -> 0 | W19: =SUBTOTAL(9,W20:W23) -> 0
A20: Chef, Kitchen Hand and Servery | C20: KITCHEN | L20: =SUMIF($C$30:$C$71,$C20,L$30:L$71) -> 0 | M20: =SUMIF($C$30:$C$71,$C20,M$30:M$71) -> 0 | N20: =SUMIF($C$30:$C$71,$C20,N$30:N$71) -> 0 | O20: =SUMIF($C$30:$C$71,$C20,O$30:O$71) -> 0 | P20: =SUMIF($C$30:$C$71,$C20,P$30:P$71) -> 0 | Q20: =SUMIF($C$30:$C$71,$C20,Q$30:Q$71) -> 0 | R20: =SUMIF($C$30:$C$71,$C20,R$30:R$71) -> 0 | T20: =SUM(L20:R20) -> 0 | V20: =IFERROR(W20/T20,0) -> 0 | W20: =SUMIFS(W$31:W$71,$C$31:$C$71,$C20) -> 0
A21: Laundry Staff | C21: LAUNDRY | L21: =SUMIF($C$30:$C$71,$C21,L$30:L$71) -> 0 | M21: =SUMIF($C$30:$C$71,$C21,M$30:M$71) -> 0 | N21: =SUMIF($C$30:$C$71,$C21,N$30:N$71) -> 0 | O21: =SUMIF($C$30:$C$71,$C21,O$30:O$71) -> 0 | P21: =SUMIF($C$30:$C$71,$C21,P$30:P$71) -> 0 | Q21: =SUMIF($C$30:$C$71,$C21,Q$30:Q$71) -> 0 | R21: =SUMIF($C$30:$C$71,$C21,R$30:R$71) -> 0 | T21: =SUM(L21:R21) -> 0 | V21: =IFERROR(W21/T21,0) -> 0 | W21: =SUMIFS(W$31:W$71,$C$31:$C$71,$C21) -> 0
A22: Drivers | C22: DRIVER | L22: =SUMIF($C$30:$C$71,$C22,L$30:L$71) -> 0 | M22: =SUMIF($C$30:$C$71,$C22,M$30:M$71) -> 0 | N22: =SUMIF($C$30:$C$71,$C22,N$30:N$71) -> 0 | O22: =SUMIF($C$30:$C$71,$C22,O$30:O$71) -> 0 | P22: =SUMIF($C$30:$C$71,$C22,P$30:P$71) -> 0 | Q22: =SUMIF($C$30:$C$71,$C22,Q$30:Q$71) -> 0 | R22: =SUMIF($C$30:$C$71,$C22,R$30:R$71) -> 0 | T22: =SUM(L22:R22) -> 0 | V22: =IFERROR(W22/T22,0) -> 0 | W22: =SUMIFS(W$31:W$71,$C$31:$C$71,$C22) -> 0
A24: MANAGEMENT & ADMIN | L24: =SUBTOTAL(9,L25:L27) -> 0 | M24: =SUBTOTAL(9,M25:M27) -> 0 | N24: =SUBTOTAL(9,N25:N27) -> 0 | O24: =SUBTOTAL(9,O25:O27) -> 0 | P24: =SUBTOTAL(9,P25:P27) -> 0 | Q24: =SUBTOTAL(9,Q25:Q27) -> 0 | R24: =SUBTOTAL(9,R25:R27) -> 0 | T24: =SUBTOTAL(9,T25:T27) -> 0 | V24: =IFERROR(W24/T24,0) -> 0 | W24: =SUBTOTAL(9,W25:W27) -> 0
A25: Facility Manager | C25: CLINICAL MANAGEMENT | L25: =SUMIF($C$30:$C$71,$C25,L$30:L$71) -> 0 | M25: =SUMIF($C$30:$C$71,$C25,M$30:M$71) -> 0 | N25: =SUMIF($C$30:$C$71,$C25,N$30:N$71) -> 0 | O25: =SUMIF($C$30:$C$71,$C25,O$30:O$71) -> 0 | P25: =SUMIF($C$30:$C$71,$C25,P$30:P$71) -> 0 | Q25: =SUMIF($C$30:$C$71,$C25,Q$30:Q$71) -> 0 | R25: =SUMIF($C$30:$C$71,$C25,R$30:R$71) -> 0 | T25: =SUM(L25:R25) -> 0 | V25: =IFERROR(W25/T25,0) -> 0 | W25: =SUMIFS(W$31:W$71,$C$31:$C$71,$C25) -> 0
A26: Care Manager | C26: NON-CLINICAL MANAGEMENT | L26: =SUMIF($C$30:$C$71,$C26,L$30:L$71) -> 0 | M26: =SUMIF($C$30:$C$71,$C26,M$30:M$71) -> 0 | N26: =SUMIF($C$30:$C$71,$C26,N$30:N$71) -> 0 | O26: =SUMIF($C$30:$C$71,$C26,O$30:O$71) -> 0 | P26: =SUMIF($C$30:$C$71,$C26,P$30:P$71) -> 0 | Q26: =SUMIF($C$30:$C$71,$C26,Q$30:Q$71) -> 0 | R26: =SUMIF($C$30:$C$71,$C26,R$30:R$71) -> 0 | T26: =SUM(L26:R26) -> 0 | V26: =IFERROR(W26/T26,0) -> 0 | W26: =SUMIFS(W$31:W$71,$C$31:$C$71,$C26) -> 0
A30: ROLE | B30: SHIFT TIME | C30: AN-ACC ALLOCATION | D30: COUNT | F30: START | G30: END | H30: Raw Time | I30: Less break | J30: Paid time | K30: Total per head count | L30: =SUBTOTAL(9,L31:L71) -> 0 | M30: =SUBTOTAL(9,M31:M71) -> 0 | N30: =SUBTOTAL(9,N31:N71) -> 0 | O30: =SUBTOTAL(9,O31:O71) -> 0 | P30: =SUBTOTAL(9,P31:P71) -> 0 | Q30: =SUBTOTAL(9,Q31:Q71) -> 0 | R30: =SUBTOTAL(9,R31:R71) -> 0 | T30: =SUBTOTAL(9,T31:T71) -> 0 | W30: =SUBTOTAL(9,W31:W71) -> 0
A31: Insert Role | B31: AM | C31: RN | D31: 1 | F31: 0.27083333 | G31: 0.60416667 | H31: =IF((G31-F31)<0,(G31+(1-F31))*24,(G31-F31)*24) -> 8 | I31: =IF(H31>5,-0.5,0) -> -0.5 | J31: =SUM(H31:I31) -> 7.5 | K31: =D31*J31 -> 7.5 | T31: =SUM(L31:S31) -> 0 | V31: =IFERROR(VLOOKUP(A31,#REF!,4,FALSE),0) -> 0 | W31: =T31*V31 -> 0
T32: =SUM(L32:S32) -> 0 | V32: =IFERROR(VLOOKUP(A32,#REF!,4,FALSE),0) -> 0 | W32: =T32*V32 -> 0
T33: =SUM(L33:S33) -> 0 | V33: =IFERROR(VLOOKUP(A33,#REF!,4,FALSE),0) -> 0 | W33: =T33*V33 -> 0
T34: =SUM(L34:S34) -> 0 | V34: =IFERROR(VLOOKUP(A34,#REF!,4,FALSE),0) -> 0 | W34: =T34*V34 -> 0
T35: =SUM(L35:S35) -> 0 | V35: =IFERROR(VLOOKUP(A35,#REF!,4,FALSE),0) -> 0 | W35: =T35*V35 -> 0
T36: =SUM(L36:S36) -> 0 | V36: =IFERROR(VLOOKUP(A36,#REF!,4,FALSE),0) -> 0 | W36: =T36*V36 -> 0
T37: =SUM(L37:S37) -> 0 | V37: =IFERROR(VLOOKUP(A37,#REF!,4,FALSE),0) -> 0 | W37: =T37*V37 -> 0
T38: =SUM(L38:S38) -> 0 | V38: =IFERROR(VLOOKUP(A38,#REF!,4,FALSE),0) -> 0 | W38: =T38*V38 -> 0
T39: =SUM(L39:S39) -> 0 | V39: =IFERROR(VLOOKUP(A39,#REF!,4,FALSE),0) -> 0 | W39: =T39*V39 -> 0
T40: =SUM(L40:S40) -> 0 | V40: =IFERROR(VLOOKUP(A40,#REF!,4,FALSE),0) -> 0 | W40: =T40*V40 -> 0
T41: =SUM(L41:S41) -> 0 | V41: =IFERROR(VLOOKUP(A41,#REF!,4,FALSE),0) -> 0 | W41: =T41*V41 -> 0
T42: =SUM(L42:S42) -> 0 | V42: =IFERROR(VLOOKUP(A42,#REF!,4,FALSE),0) -> 0 | W42: =T42*V42 -> 0
T43: =SUM(L43:S43) -> 0 | V43: =IFERROR(VLOOKUP(A43,#REF!,4,FALSE),0) -> 0 | W43: =T43*V43 -> 0
... T51: =SUM(L51:S51) -> 0 | V51: =IFERROR(VLOOKUP(A51,#REF!,4,FALSE),0) -> 0 | W51: =T51*V51 -> 0
V52: =IFERROR(VLOOKUP(A52,#REF!,4,FALSE),0) -> 0 | W52: =T52*V52 -> 0
V53: =IFERROR(VLOOKUP(A53,#REF!,4,FALSE),0) -> 0 | W53: =T53*V53 -> 0
V54: =IFERROR(VLOOKUP(A54,#REF!,4,FALSE),0) -> 0 | W54: =T54*V54 -> 0
V55: =IFERROR(VLOOKUP(A55,#REF!,4,FALSE),0) -> 0 | W55: =T55*V55 -> 0
V56: =IFERROR(VLOOKUP(A56,#REF!,4,FALSE),0) -> 0 | W56: =T56*V56 -> 0
V57: =IFERROR(VLOOKUP(A57,#REF!,4,FALSE),0) -> 0 | W57: =T57*V57 -> 0
V58: =IFERROR(VLOOKUP(A58,#REF!,4,FALSE),0) -> 0 | W58: =T58*V58 -> 0
...

Sheet Roster - G4 - Services
A1: ='Primary Inputs'!$B$5 -> Christadelphian Aged Care
A3: Current Roster Budget
A5: Roster Code (in this model) | B5: Site(s) | C5: Wing | D5: Wing Type | E5: Maximum number of beds/licences
A6: ='Primary Inputs'!A12 -> G4 | B6: =VLOOKUP($A6,'Primary Inputs'!$A$9:$J$13,2,FALSE) -> Ashburn House | C6: =VLOOKUP($A6,'Primary Inputs'!$A$9:$J$13,3,FALSE) -> Hidden | D6: =VLOOKUP($A6,'Primary Inputs'!$A$9:$J$13,4,FALSE) -> Roster Only | E6: =VLOOKUP($A6,'Primary Inputs'!$A$9:$J$13,5,FALSE) -> 0
L9: Roster Hours per Day | T9: Total Weekly Hours
A10: Location | B10: Shift | C10: Role | D10: Headcount per shift | E10: Notes | F10: Shift Start | G10: Shift End | H10: Shift Hours (Excl Break) | I10: Break | J10: Shift less breaks | K10: Total Hours | L10: Mon | M10: Tue | N10: Wed | O10: Thu | P10: Fri | Q10: Sat | R10: Sun | V10: AN-ACC Allocation (%) | W10: An-ACC Hours
A12: ="TOTAL "&$C$6&" ROSTER" -> TOTAL Hidden ROSTER | L12: =SUBTOTAL(9,L13:L28) -> 0 | M12: =SUBTOTAL(9,M13:M28) -> 0 | N12: =SUBTOTAL(9,N13:N28) -> 0 | O12: =SUBTOTAL(9,O13:O28) -> 0 | P12: =SUBTOTAL(9,P13:P28) -> 0 | Q12: =SUBTOTAL(9,Q13:Q28) -> 0 | R12: =SUBTOTAL(9,R13:R28) -> 0 | T12: =SUBTOTAL(9,T13:T28) -> 0 | V12: =IFERROR(W12/T12,0) -> 0 | W12: =SUBTOTAL(9,W13:W28) -> 0
A13: CARE ROSTER | L13: =SUBTOTAL(9,L14:L15) -> 0 | M13: =SUBTOTAL(9,M14:M15) -> 0 | N13: =SUBTOTAL(9,N14:N15) -> 0 | O13: =SUBTOTAL(9,O14:O15) -> 0 | P13: =SUBTOTAL(9,P14:P15) -> 0 | Q13: =SUBTOTAL(9,Q14:Q15) -> 0 | R13: =SUBTOTAL(9,R14:R15) -> 0 | T13: =SUBTOTAL(9,T14:T15) -> 0 | V13: =IFERROR(W13/T13,0) -> 0 | W13: =SUBTOTAL(9,W14:W15) -> 0
A14: Registered Nurses | C14: RN | L14: =SUMIF($C$30:$C$71,$C14,L$30:L$71) -> 0 | M14: =SUMIF($C$30:$C$71,$C14,M$30:M$71) -> 0 | N14: =SUMIF($C$30:$C$71,$C14,N$30:N$71) -> 0 | O14: =SUMIF($C$30:$C$71,$C14,O$30:O$71) -> 0 | P14: =SUMIF($C$30:$C$71,$C14,P$30:P$71) -> 0 | Q14: =SUMIF($C$30:$C$71,$C14,Q$30:Q$71) -> 0 | R14: =SUMIF($C$30:$C$71,$C14,R$30:R$71) -> 0 | T14: =SUM(L14:R14) -> 0 | V14: =IFERROR(W14/T14,0) -> 0 | W14: =SUMIFS(W$31:W$71,$C$31:$C$71,$C14) -> 0
A15: Carers and ENs | B15: RN Hours | C15: CARER | L15: =SUMIF($C$30:$C$71,$C15,L$30:L$71) -> 0 | M15: =SUMIF($C$30:$C$71,$C15,M$30:M$71) -> 0 | N15: =SUMIF($C$30:$C$71,$C15,N$30:N$71) -> 0 | O15: =SUMIF($C$30:$C$71,$C15,O$30:O$71) -> 0 | P15: =SUMIF($C$30:$C$71,$C15,P$30:P$71) -> 0 | Q15: =SUMIF($C$30:$C$71,$C15,Q$30:Q$71) -> 0 | R15: =SUMIF($C$30:$C$71,$C15,R$30:R$71) -> 0 | T15: =SUM(L15:R15) -> 0 | V15: =IFERROR(W15/T15,0) -> 0 | W15: =SUMIFS(W$31:W$71,$C$31:$C$71,$C15) -> 0
A17: LIFESTYLE | C17: LIFESTYLE | L17: =SUMIF($C$30:$C$71,$C17,L$30:L$71) -> 0 | M17: =SUMIF($C$30:$C$71,$C17,M$30:M$71) -> 0 | N17: =SUMIF($C$30:$C$71,$C17,N$30:N$71) -> 0 | O17: =SUMIF($C$30:$C$71,$C17,O$30:O$71) -> 0 | P17: =SUMIF($C$30:$C$71,$C17,P$30:P$71) -> 0 | Q17: =SUMIF($C$30:$C$71,$C17,Q$30:Q$71) -> 0 | R17: =SUMIF($C$30:$C$71,$C17,R$30:R$71) -> 0 | T17: =SUM(L17:R17) -> 0 | V17: =IFERROR(W17/T17,0) -> 0 | W17: =SUMIFS(W$31:W$71,$A$31:$A$71,$A17) -> 0
A19: KITCHEN & LAUNDRY | L19: =SUBTOTAL(9,L20:L23) -> 0 | M19: =SUBTOTAL(9,M20:M23) -> 0 | N19: =SUBTOTAL(9,N20:N23) -> 0 | O19: =SUBTOTAL(9,O20:O23) -> 0 | P19: =SUBTOTAL(9,P20:P23) -> 0 | Q19: =SUBTOTAL(9,Q20:Q23) -> 0 | R19: =SUBTOTAL(9,R20:R23) -> 0 | T19: =SUBTOTAL(9,T20:T23) -> 0 | V19: =IFERROR(W19/T19,0) -> 0 | W19: =SUBTOTAL(9,W20:W23) -> 0
A20: Chef, Kitchen Hand and Servery | C20: KITCHEN | L20: =SUMIF($C$30:$C$71,$C20,L$30:L$71) -> 0 | M20: =SUMIF($C$30:$C$71,$C20,M$30:M$71) -> 0 | N20: =SUMIF($C$30:$C$71,$C20,N$30:N$71) -> 0 | O20: =SUMIF($C$30:$C$71,$C20,O$30:O$71) -> 0 | P20: =SUMIF($C$30:$C$71,$C20,P$30:P$71) -> 0 | Q20: =SUMIF($C$30:$C$71,$C20,Q$30:Q$71) -> 0 | R20: =SUMIF($C$30:$C$71,$C20,R$30:R$71) -> 0 | T20: =SUM(L20:R20) -> 0 | V20: =IFERROR(W20/T20,0) -> 0 | W20: =SUMIFS(W$31:W$71,$C$31:$C$71,$C20) -> 0
A21: Laundry Staff | C21: LAUNDRY | L21: =SUMIF($C$30:$C$71,$C21,L$30:L$71) -> 0 | M21: =SUMIF($C$30:$C$71,$C21,M$30:M$71) -> 0 | N21: =SUMIF($C$30:$C$71,$C21,N$30:N$71) -> 0 | O21: =SUMIF($C$30:$C$71,$C21,O$30:O$71) -> 0 | P21: =SUMIF($C$30:$C$71,$C21,P$30:P$71) -> 0 | Q21: =SUMIF($C$30:$C$71,$C21,Q$30:Q$71) -> 0 | R21: =SUMIF($C$30:$C$71,$C21,R$30:R$71) -> 0 | T21: =SUM(L21:R21) -> 0 | V21: =IFERROR(W21/T21,0) -> 0 | W21: =SUMIFS(W$31:W$71,$C$31:$C$71,$C21) -> 0
A22: Drivers | C22: DRIVER | L22: =SUMIF($C$30:$C$71,$C22,L$30:L$71) -> 0 | M22: =SUMIF($C$30:$C$71,$C22,M$30:M$71) -> 0 | N22: =SUMIF($C$30:$C$71,$C22,N$30:N$71) -> 0 | O22: =SUMIF($C$30:$C$71,$C22,O$30:O$71) -> 0 | P22: =SUMIF($C$30:$C$71,$C22,P$30:P$71) -> 0 | Q22: =SUMIF($C$30:$C$71,$C22,Q$30:Q$71) -> 0 | R22: =SUMIF($C$30:$C$71,$C22,R$30:R$71) -> 0 | T22: =SUM(L22:R22) -> 0 | V22: =IFERROR(W22/T22,0) -> 0 | W22: =SUMIFS(W$31:W$71,$C$31:$C$71,$C22) -> 0
A24: MANAGEMENT & ADMIN | L24: =SUBTOTAL(9,L25:L27) -> 0 | M24: =SUBTOTAL(9,M25:M27) -> 0 | N24: =SUBTOTAL(9,N25:N27) -> 0 | O24: =SUBTOTAL(9,O25:O27) -> 0 | P24: =SUBTOTAL(9,P25:P27) -> 0 | Q24: =SUBTOTAL(9,Q25:Q27) -> 0 | R24: =SUBTOTAL(9,R25:R27) -> 0 | T24: =SUBTOTAL(9,T25:T27) -> 0 | V24: =IFERROR(W24/T24,0) -> 0 | W24: =SUBTOTAL(9,W25:W27) -> 0
A25: Facility Manager | C25: CLINICAL MANAGEMENT | L25: =SUMIF($C$30:$C$71,$C25,L$30:L$71) -> 0 | M25: =SUMIF($C$30:$C$71,$C25,M$30:M$71) -> 0 | N25: =SUMIF($C$30:$C$71,$C25,N$30:N$71) -> 0 | O25: =SUMIF($C$30:$C$71,$C25,O$30:O$71) -> 0 | P25: =SUMIF($C$30:$C$71,$C25,P$30:P$71) -> 0 | Q25: =SUMIF($C$30:$C$71,$C25,Q$30:Q$71) -> 0 | R25: =SUMIF($C$30:$C$71,$C25,R$30:R$71) -> 0 | T25: =SUM(L25:R25) -> 0 | V25: =IFERROR(W25/T25,0) -> 0 | W25: =SUMIFS(W$31:W$71,$C$31:$C$71,$C25) -> 0
A26: Care Manager | C26: NON-CLINICAL MANAGEMENT | L26: =SUMIF($C$30:$C$71,$C26,L$30:L$71) -> 0 | M26: =SUMIF($C$30:$C$71,$C26,M$30:M$71) -> 0 | N26: =SUMIF($C$30:$C$71,$C26,N$30:N$71) -> 0 | O26: =SUMIF($C$30:$C$71,$C26,O$30:O$71) -> 0 | P26: =SUMIF($C$30:$C$71,$C26,P$30:P$71) -> 0 | Q26: =SUMIF($C$30:$C$71,$C26,Q$30:Q$71) -> 0 | R26: =SUMIF($C$30:$C$71,$C26,R$30:R$71) -> 0 | T26: =SUM(L26:R26) -> 0 | V26: =IFERROR(W26/T26,0) -> 0 | W26: =SUMIFS(W$31:W$71,$C$31:$C$71,$C26) -> 0
A30: ROLE | B30: SHIFT TIME | C30: AN-ACC ALLOCATION | D30: COUNT | F30: START | G30: END | H30: Raw Time | I30: Less break | J30: Paid time | K30: Total per head count | L30: =SUBTOTAL(9,L31:L71) -> 0 | M30: =SUBTOTAL(9,M31:M71) -> 0 | N30: =SUBTOTAL(9,N31:N71) -> 0 | O30: =SUBTOTAL(9,O31:O71) -> 0 | P30: =SUBTOTAL(9,P31:P71) -> 0 | Q30: =SUBTOTAL(9,Q31:Q71) -> 0 | R30: =SUBTOTAL(9,R31:R71) -> 0 | T30: =SUBTOTAL(9,T31:T71) -> 0 | W30: =SUBTOTAL(9,W31:W71) -> 0
A31: KITCHEN HAND | B31: AM | C31: KITCHEN | D31: 1 | F31: 0.25 | G31: 0.58333333 | H31: =IF((G31-F31)<0,(G31+(1-F31))*24,(G31-F31)*24) -> 8 | I31: =IF(H31>5,-0.5,0) -> -0.5 | J31: =SUM(H31:I31) -> 7.5 | K31: =D31*J31 -> 7.5 | T31: =SUM(L31:S31) -> 0 | V31: =IFERROR(VLOOKUP(A31,#REF!,4,FALSE),0) -> 0 | W31: =T31*V31 -> 0
T32: =SUM(L32:S32) -> 0 | V32: =IFERROR(VLOOKUP(A32,#REF!,4,FALSE),0) -> 0 | W32: =T32*V32 -> 0
T33: =SUM(L33:S33) -> 0 | V33: =IFERROR(VLOOKUP(A33,#REF!,4,FALSE),0) -> 0 | W33: =T33*V33 -> 0
T34: =SUM(L34:S34) -> 0 | V34: =IFERROR(VLOOKUP(A34,#REF!,4,FALSE),0) -> 0 | W34: =T34*V34 -> 0
T35: =SUM(L35:S35) -> 0 | V35: =IFERROR(VLOOKUP(A35,#REF!,4,FALSE),0) -> 0 | W35: =T35*V35 -> 0
T36: =SUM(L36:S36) -> 0 | V36: =IFERROR(VLOOKUP(A36,#REF!,4,FALSE),0) -> 0 | W36: =T36*V36 -> 0
T37: =SUM(L37:S37) -> 0 | V37: =IFERROR(VLOOKUP(A37,#REF!,4,FALSE),0) -> 0 | W37: =T37*V37 -> 0
T38: =SUM(L38:S38) -> 0 | V38: =IFERROR(VLOOKUP(A38,#REF!,4,FALSE),0) -> 0 | W38: =T38*V38 -> 0
T39: =SUM(L39:S39) -> 0 | V39: =IFERROR(VLOOKUP(A39,#REF!,4,FALSE),0) -> 0 | W39: =T39*V39 -> 0
T40: =SUM(L40:S40) -> 0 | V40: =IFERROR(VLOOKUP(A40,#REF!,4,FALSE),0) -> 0 | W40: =T40*V40 -> 0
T41: =SUM(L41:S41) -> 0 | V41: =IFERROR(VLOOKUP(A41,#REF!,4,FALSE),0) -> 0 | W41: =T41*V41 -> 0
T42: =SUM(L42:S42) -> 0 | V42: =IFERROR(VLOOKUP(A42,#REF!,4,FALSE),0) -> 0 | W42: =T42*V42 -> 0
T43: =SUM(L43:S43) -> 0 | V43: =IFERROR(VLOOKUP(A43,#REF!,4,FALSE),0) -> 0 | W43: =T43*V43 -> 0
... T51: =SUM(L51:S51) -> 0 | V51: =IFERROR(VLOOKUP(A51,#REF!,4,FALSE),0) -> 0 | W51: =T51*V51 -> 0
V52: =IFERROR(VLOOKUP(A52,#REF!,4,FALSE),0) -> 0 | W52: =T52*V52 -> 0
V53: =IFERROR(VLOOKUP(A53,#REF!,4,FALSE),0) -> 0 | W53: =T53*V53 -> 0
V54: =IFERROR(VLOOKUP(A54,#REF!,4,FALSE),0) -> 0 | W54: =T54*V54 -> 0
V55: =IFERROR(VLOOKUP(A55,#REF!,4,FALSE),0) -> 0 | W55: =T55*V55 -> 0
V56: =IFERROR(VLOOKUP(A56,#REF!,4,FALSE),0) -> 0 | W56: =T56*V56 -> 0
V57: =IFERROR(VLOOKUP(A57,#REF!,4,FALSE),0) -> 0 | W57: =T57*V57 -> 0
V58: =IFERROR(VLOOKUP(A58,#REF!,4,FALSE),0) -> 0 | W58: =T58*V58 -> 0
...

Sheet Roster - G5 - Mgmt
A1: ='Primary Inputs'!$B$5 -> Christadelphian Aged Care
A3: Current Roster Budget
A5: Roster Code (in this model) | B5: Site(s) | C5: Wing | D5: Wing Type | E5: Maximum number of beds/licences
A6: ='Primary Inputs'!A13 -> G5 | B6: =VLOOKUP($A6,'Primary Inputs'!$A$9:$J$13,2,FALSE) -> Ashburn House | C6: =VLOOKUP($A6,'Primary Inputs'!$A$9:$J$13,3,FALSE) -> MANAGEMENT | D6: =VLOOKUP($A6,'Primary Inputs'!$A$9:$J$13,4,FALSE) -> Roster Only | E6: =VLOOKUP($A6,'Primary Inputs'!$A$9:$J$13,5,FALSE) -> 0
L9: Roster Hours per Day | T9: Total Weekly Hours
A10: Location | B10: Shift | C10: Role | D10: Headcount per shift | E10: Notes | F10: Shift Start | G10: Shift End | H10: Shift Hours (Excl Break) | I10: Break | J10: Shift less breaks | K10: Total Hours | L10: Mon | M10: Tue | N10: Wed | O10: Thu | P10: Fri | Q10: Sat | R10: Sun | V10: AN-ACC Allocation (%) | W10: An-ACC Hours
A12: ="TOTAL "&$C$6&" ROSTER" -> TOTAL MANAGEMENT ROSTER | L12: =SUBTOTAL(9,L13:L28) -> 16 | M12: =SUBTOTAL(9,M13:M28) -> 16 | N12: =SUBTOTAL(9,N13:N28) -> 16 | O12: =SUBTOTAL(9,O13:O28) -> 16 | P12: =SUBTOTAL(9,P13:P28) -> 16 | Q12: =SUBTOTAL(9,Q13:Q28) -> 0 | R12: =SUBTOTAL(9,R13:R28) -> 0 | T12: =SUBTOTAL(9,T13:T28) -> 80 | V12: =IFERROR(W12/T12,0) -> 0.6 | W12: =SUBTOTAL(9,W13:W28) -> 48
A13: CARE ROSTER | L13: =SUBTOTAL(9,L14:L15) -> 0 | M13: =SUBTOTAL(9,M14:M15) -> 0 | N13: =SUBTOTAL(9,N14:N15) -> 0 | O13: =SUBTOTAL(9,O14:O15) -> 0 | P13: =SUBTOTAL(9,P14:P15) -> 0 | Q13: =SUBTOTAL(9,Q14:Q15) -> 0 | R13: =SUBTOTAL(9,R14:R15) -> 0 | T13: =SUBTOTAL(9,T14:T15) -> 0 | V13: =IFERROR(W13/T13,0) -> 0 | W13: =SUBTOTAL(9,W14:W15) -> 0
A14: Registered Nurses | C14: RN | L14: =SUMIF($C$30:$C$71,$C14,L$30:L$71) -> 0 | M14: =SUMIF($C$30:$C$71,$C14,M$30:M$71) -> 0 | N14: =SUMIF($C$30:$C$71,$C14,N$30:N$71) -> 0 | O14: =SUMIF($C$30:$C$71,$C14,O$30:O$71) -> 0 | P14: =SUMIF($C$30:$C$71,$C14,P$30:P$71) -> 0 | Q14: =SUMIF($C$30:$C$71,$C14,Q$30:Q$71) -> 0 | R14: =SUMIF($C$30:$C$71,$C14,R$30:R$71) -> 0 | T14: =SUM(L14:R14) -> 0 | V14: =IFERROR(W14/T14,0) -> 0 | W14: =SUMIFS(W$31:W$71,$C$31:$C$71,$C14) -> 0
A15: Carers and ENs | B15: RN Hours | C15: CARER | L15: =SUMIF($C$30:$C$71,$C15,L$30:L$71) -> 0 | M15: =SUMIF($C$30:$C$71,$C15,M$30:M$71) -> 0 | N15: =SUMIF($C$30:$C$71,$C15,N$30:N$71) -> 0 | O15: =SUMIF($C$30:$C$71,$C15,O$30:O$71) -> 0 | P15: =SUMIF($C$30:$C$71,$C15,P$30:P$71) -> 0 | Q15: =SUMIF($C$30:$C$71,$C15,Q$30:Q$71) -> 0 | R15: =SUMIF($C$30:$C$71,$C15,R$30:R$71) -> 0 | T15: =SUM(L15:R15) -> 0 | V15: =IFERROR(W15/T15,0) -> 0 | W15: =SUMIFS(W$31:W$71,$C$31:$C$71,$C15) -> 0
